Workbook

Sheet Anotações Gerais
A1: Nome | C1: Claudinei Rogério Gasparoto | E1: Agenda
F2: Seg | G2: Ter | H2: Qua | I2: Qui | J2: Sex | K2: Sáb | L2: Dom
A3: Objetivo | E3: Atividade
E4: Tempo máximo
A5: Obs importante 1 | E5: Tempo ideal
A6: Obs importante 2 | E6: Atividade 2
E7: Tempo máximo 2
A8: Anotações gerais | E8: Tempo ideal 2
E10: Roteiro
E11: Explicar o motivo da avaliação e o serviços que serão feitos
E12: Perguntar sobre histórico com AF (relação com AF)
E13: Histórico Médico (ver anamnese)
E14: Se faz algum tratamento médico ou possui alguma doença
A15: 45933 | E15: Mais alguma coisa?
E16: Objetivos?
A17: 45938 | E17: Agenda
A20: 46064

Sheet Avaliação
A1: Nome | B1: ='Anotações Gerais'!C1 -> Claudinei Rogério Gasparoto | F1: Data de Nascimento | H1: 26471 | J1: Sexo | K1: Masculino | N1: NAF | O1: Ativo | R1: PAR-Q e VOCÊ | T1: Negativo | V1: Estratificação do Risco ACSM | Y1: Baixo risco
A2: Versão 4.5.11 | C2: △%Total | D2: Av1 | E2: △% | F2: Av2 | G2: △% | H2: Av3 | I2: △% | J2: Av4 | K2: △% | L2: Av5 | M2: △% | N2: Av6 | O2: △% | P2: Av7 | Q2: △% | R2: Av8 | S2: △% | T2: Av9 | U2: △% | V2: Av10 | W2: △% | X2: Av11 | Y2: △% | Z2: Av12 | AA2: △% | AB2: Av13 | AC2: △% | AD2: Av14 | AE2: △% | AF2: Av15
A3: Data da avaliação(DD/MM/YYYY) | C3: - | D3: 44517 | F3: 44733 | H3: 44949 | J3: 45078 | L3: 45301 | N3: 45433 | P3: 45611 | R3: 45752 | T3: 45829 | V3: 45938 | X3: 45993 | Z3: 46064
A4: Tipo de Avaliação | R4: COMPLETA | T4: PARCIAL | V4: COMPLETA | X4: PARCIAL | Z4: COMPLETA
A5: Hora da avaliação(hh:mm) | C5: - | D5: 0.47916667 | E5: - | F5: 0.47916667 | G5: - | H5: 0.47916667 | I5: - | J5: 0.47916667 | K5: - | L5: 0.625 | M5: - | N5: 0.58333333 | O5: - | P5: 0.33333333 | Q5: - | R5: 0.375 | S5: - | T5: 0.33333333 | U5: - | V5: 0.33333333 | W5: - | X5: 0.33333333 | Y5: - | Z5: 0.72916667 | AA5: - | AC5: - | AE5: -
A6: Avaliador | C6: - | D6: Luis Felipe | E6: - | F6: Luis Felipe | G6: - | H6: Luis Felipe | I6: - | J6: Luis Felipe | K6: - | L6: Luis Felipe | M6: - | N6: Luis Felipe | O6: - | P6: Luis Felipe | Q6: - | R6: Luis Felipe | S6: - | T6: Luis Felipe | U6: - | V6: Luis Felipe | W6: - | X6: Luis Felipe | Y6: - | Z6: Luis Felipe | AA6: - | AC6: - | AE6: -
A7: Idade | C7: - | D7: =IF(D3="","",DATEDIF($H$1,D3,"Y")) -> 49 | E7: - | F7: =IF(F3="","",DATEDIF($H$1,F3,"Y")) -> 50 | G7: - | H7: =IF(H3="","",DATEDIF($H$1,H3,"Y")) -> 50 | I7: - | J7: =IF(J3="","",DATEDIF($H$1,J3,"Y")) -> 50 | K7: - | L7: =IF(L3="","",DATEDIF($H$1,L3,"Y")) -> 51 | M7: - | N7: =IF(N3="","",DATEDIF($H$1,N3,"Y")) -> 51 | O7: - | P7: =IF(P3="","",DATEDIF($H$1,P3,"Y")) -> 52 | Q7: - | R7: =IF(R3="","",DATEDIF($H$1,R3,"Y")) -> 52 | S7: - | T7: =IF(T3="","",DATEDIF($H$1,T3,"Y")) -> 53 | U7: - | V7: =IF(V3="","",DATEDIF($H$1,V3,"Y")) -> 53 | W7: - | X7: =IF(X3="","",DATEDIF($H$1,X3,"Y")) -> 53 | Y7: - | Z7: =IF(Z3="","",DATEDIF($H$1,Z3,"Y")) -> 53 | AA7: - | AB7: =IF(AB3="","",DATEDIF($H$1,AB3,"Y")) | AC7: - | AD7: =IF(AD3="","",DATEDIF($H$1,AD3,"Y")) | AE7: - | AF7: =IF(AF3="","",DATEDIF($H$1,AF3,"Y"))
A8: Data da reavaliação | C8: - | D8: =IF(D3="","",D3+56) -> 44573 | E8: - | F8: =IF(F3="","",F3+56) -> 44789 | G8: - | H8: =IF(H3="","",H3+56) -> 45005 | I8: - | J8: =IF(J3="","",J3+56) -> 45134 | K8: - | L8: =IF(L3="","",L3+56) -> 45357 | M8: - | N8: =IF(N3="","",N3+56) -> 45489 | O8: - | P8: =IF(P3="","",P3+56) -> 45667 | Q8: - | R8: =IF(R3="","",R3+56) -> 45808 | S8: - | T8: =IF(T3="","",T3+56) -> 45885 | U8: - | V8: =IF(V3="","",V3+56) -> 45994 | W8: - | X8: =IF(X3="","",X3+56) -> 46049 | Y8: - | Z8: =IF(Z3="","",Z3+56) -> 46120 | AA8: - | AB8: =IF(AB3="","",AB3+56) | AC8: - | AD8: =IF(AD3="","",AD3+56) | AE8: - | AF8: =IF(AF3="","",AF3+56)
A9: Peso e altura | C9: ='BD tratado'!A147 -> 15 | D9: 1 | F9: 2 | H9: 3 | J9: 4 | L9: 5 | N9: 6 | P9: 7 | R9: 8 | T9: 9 | V9: 10 | X9: 11 | Z9: 12 | AB9: 13 | AD9: 14 | AF9: 15
A10: Peso (kg) | C10: ='BD tratado'!D8 -> #NAME? | D10: 75.7 | E10: =IF(OR(D10="",F10=""),"-",(F10-D10)*100/D10) -> -10.171731 | F10: 68 | G10: =IF(OR(F10="",H10=""),"-",(H10-F10)*100/F10) -> -7.7941176 | H10: 62.7 | I10: =IF(OR(H10="",J10=""),"-",(J10-H10)*100/H10) -> 3.5087719 | J10: 64.9 | K10: =IF(OR(J10="",L10=""),"-",(L10-J10)*100/J10) -> 4.3143297 | L10: 67.7 | M10: =IF(OR(L10="",N10=""),"-",(N10-L10)*100/L10) -> -0.14771049 | N10: 67.6 | O10: =IF(OR(N10="",P10=""),"-",(P10-N10)*100/N10) -> 0 | P10: 67.6 | Q10: =IF(OR(P10="",R10=""),"-",(R10-P10)*100/P10) -> 4.5857988 | R10: 70.7 | S10: =IF(OR(R10="",T10=""),"-",(T10-R10)*100/R10) -> -2.4045262 | T10: 69 | U10: =IF(OR(T10="",V10=""),"-",(V10-T10)*100/T10) -> -0.57971014 | V10: 68.6 | W10: =IF(OR(V10="",X10=""),"-",(X10-V10)*100/V10) -> -2.3323615 | X10: 67 | Y10: =IF(OR(X10="",Z10=""),"-",(Z10-X10)*100/X10) -> 4.4776119 | Z10: 70 | AA10: =IF(OR(Z10="",AB10=""),"-",(AB10-Z10)*100/Z10) -> - | AC10: =IF(OR(AB10="",AD10=""),"-",(AD10-AB10)*100/AB10) -> - | AE10: =IF(OR(AD10="",AF10=""),"-",(AF10-AD10)*100/AD10) -> -
A11: Estatura (cm) | C11: ='BD tratado'!D9 -> #NAME? | D11: 172.8 | E11: =IF(OR(D11="",F11=""),"-",(F11-D11)*100/D11) -> -0.46296296 | F11: 172 | G11: =IF(OR(F11="",H11=""),"-",(H11-F11)*100/F11) -> 0 | H11: 172 | I11: =IF(OR(H11="",J11=""),"-",(J11-H11)*100/H11) -> 0 | J11: 172 | K11: =IF(OR(J11="",L11=""),"-",(L11-J11)*100/J11) -> 0 | L11: 172 | M11: =IF(OR(L11="",N11=""),"-",(N11-L11)*100/L11) -> 0 | N11: 172 | O11: =IF(OR(N11="",P11=""),"-",(P11-N11)*100/N11) -> 0 | P11: 172 | R11: 172 | S11: =IF(OR(R11="",T11=""),"-",(T11-R11)*100/R11) -> 0 | T11: 172 | U11: =IF(OR(T11="",V11=""),"-",(V11-T11)*100/T11) -> 0 | V11: 172 | W11: =IF(OR(V11="",X11=""),"-",(X11-V11)*100/V11) -> 0 | X11: 172 | Y11: =IF(OR(X11="",Z11=""),"-",(Z11-X11)*100/X11) -> 0 | Z11: 172 | AA11: =IF(OR(Z11="",AB11=""),"-",(AB11-Z11)*100/Z11) -> - | AC11: =IF(OR(AB11="",AD11=""),"-",(AD11-AB11)*100/AB11) -> - | AE11: =IF(OR(AD11="",AF11=""),"-",(AF11-AD11)*100/AD11) -> -
A12: Circunferência
A13: Escapular | C13: ='BD tratado'!D11 -> #NAME? | D13: 116.8 | E13: =IF(OR(D13="",F13=""),"-",(F13-D13)*100/D13) -> -4.9657534 | F13: 111 | G13: =IF(OR(F13="",H13=""),"-",(H13-F13)*100/F13) -> -1.8018018 | H13: 109 | I13: =IF(OR(H13="",J13=""),"-",(J13-H13)*100/H13) -> 1.3761468 | J13: 110.5 | K13: =IF(OR(J13="",L13=""),"-",(L13-J13)*100/J13) -> 1.8099548 | L13: 112.5 | M13: =IF(OR(L13="",N13=""),"-",(N13-L13)*100/L13) -> -0.44444444 | N13: 112 | O13: =IF(OR(N13="",P13=""),"-",(P13-N13)*100/N13) -> 0.89285714 | P13: 113 | Q13: =IF(OR(P13="",R13=""),"-",(R13-P13)*100/P13) -> 0 | R13: 113 | S13: =IF(OR(R13="",T13=""),"-",(T13-R13)*100/R13) -> 0 | T13: 113 | U13: =IF(OR(T13="",V13=""),"-",(V13-T13)*100/T13) -> 0 | V13: 113 | W13: =IF(OR(V13="",X13=""),"-",(X13-V13)*100/V13) -> - | Y13: =IF(OR(X13="",Z13=""),"-",(Z13-X13)*100/X13) -> - | AA13: =IF(OR(Z13="",AB13=""),"-",(AB13-Z13)*100/Z13) -> - | AC13: =IF(OR(AB13="",AD13=""),"-",(AD13-AB13)*100/AB13) -> - | AE13: =IF(OR(AD13="",AF13=""),"-",(AF13-AD13)*100/AD13) -> -
A14: Torácica Inspirada | C14: ='BD tratado'!D12 -> #NAME? | D14: 99 | E14: =IF(OR(D14="",F14=""),"-",(F14-D14)*100/D14) -> -3.030303 | F14: 96 | G14: =IF(OR(F14="",H14=""),"-",(H14-F14)*100/F14) -> -2.0833333 | H14: 94 | I14: =IF(OR(H14="",J14=""),"-",(J14-H14)*100/H14) -> 1.0638298 | J14: 95 | K14: =IF(OR(J14="",L14=""),"-",(L14-J14)*100/J14) -> 1.5789474 | L14: 96.5 | M14: =IF(OR(L14="",N14=""),"-",(N14-L14)*100/L14) -> 0.51813472 | N14: 97 | O14: =IF(OR(N14="",P14=""),"-",(P14-N14)*100/N14) -> 0 | P14: 97 | Q14: =IF(OR(P14="",R14=""),"-",(R14-P14)*100/P14) -> -1.0309278 | R14: 96 | S14: =IF(OR(R14="",T14=""),"-",(T14-R14)*100/R14) -> 1.0416667 | T14: 97 | U14: =IF(OR(T14="",V14=""),"-",(V14-T14)*100/T14) -> -1.5463918 | V14: 95.5 | W14: =IF(OR(V14="",X14=""),"-",(X14-V14)*100/V14) -> - | Y14: =IF(OR(X14="",Z14=""),"-",(Z14-X14)*100/X14) -> - | AA14: =IF(OR(Z14="",AB14=""),"-",(AB14-Z14)*100/Z14) -> - | AC14: =IF(OR(AB14="",AD14=""),"-",(AD14-AB14)*100/AB14) -> - | AE14: =IF(OR(AD14="",AF14=""),"-",(AF14-AD14)*100/AD14) -> -
A15: Torácica Expirada | C15: ='BD tratado'!D13 -> #NAME? | D15: 97 | E15: =IF(OR(D15="",F15=""),"-",(F15-D15)*100/D15) -> -6.185567 | F15: 91 | G15: =IF(OR(F15="",H15=""),"-",(H15-F15)*100/F15) -> -3.2967033 | H15: 88 | I15: =IF(OR(H15="",J15=""),"-",(J15-H15)*100/H15) -> 2.2727273 | J15: 90 | K15: =IF(OR(J15="",L15=""),"-",(L15-J15)*100/J15) -> 2.2222222 | L15: 92 | M15: =IF(OR(L15="",N15=""),"-",(N15-L15)*100/L15) -> 0.54347826 | N15: 92.5 | O15: =IF(OR(N15="",P15=""),"-",(P15-N15)*100/N15) -> 0 | P15: 92.5 | Q15: =IF(OR(P15="",R15=""),"-",(R15-P15)*100/P15) -> -0.54054054 | R15: 92 | S15: =IF(OR(R15="",T15=""),"-",(T15-R15)*100/R15) -> -0.54347826 | T15: 91.5 | U15: =IF(OR(T15="",V15=""),"-",(V15-T15)*100/T15) -> 1.0928962 | V15: 92.5 | W15: =IF(OR(V15="",X15=""),"-",(X15-V15)*100/V15) -> - | Y15: =IF(OR(X15="",Z15=""),"-",(Z15-X15)*100/X15) -> - | AA15: =IF(OR(Z15="",AB15=""),"-",(AB15-Z15)*100/Z15) -> - | AC15: =IF(OR(AB15="",AD15=""),"-",(AD15-AB15)*100/AB15) -> - | AE15: =IF(OR(AD15="",AF15=""),"-",(AF15-AD15)*100/AD15) -> -
A16: Abdominal | C16: ='BD tratado'!D14 -> #NAME? | D16: 88.5 | E16: =IF(OR(D16="",F16=""),"-",(F16-D16)*100/D16) -> -19.20904 | F16: 71.5 | G16: =IF(OR(F16="",H16=""),"-",(H16-F16)*100/F16) -> 2.7972028 | H16: 73.5 | I16: =IF(OR(H16="",J16=""),"-",(J16-H16)*100/H16) -> 1.3605442 | J16: 74.5 | K16: =IF(OR(J16="",L16=""),"-",(L16-J16)*100/J16) -> 4.0268456 | L16: 77.5 | M16: =IF(OR(L16="",N16=""),"-",(N16-L16)*100/L16) -> -1.9354839 | N16: 76 | O16: =IF(OR(N16="",P16=""),"-",(P16-N16)*100/N16) -> 1.3157895 | P16: 77 | Q16: =IF(OR(P16="",R16=""),"-",(R16-P16)*100/P16) -> 2.5974026 | R16: 79 | S16: =IF(OR(R16="",T16=""),"-",(T16-R16)*100/R16) -> -1.8987342 | T16: 77.5 | U16: =IF(OR(T16="",V16=""),"-",(V16-T16)*100/T16) -> 0.64516129 | V16: 78 | W16: =IF(OR(V16="",X16=""),"-",(X16-V16)*100/V16) -> -2.5641026 | X16: 76 | Y16: =IF(OR(X16="",Z16=""),"-",(Z16-X16)*100/X16) -> 2.6315789 | Z16: 78 | AA16: =IF(OR(Z16="",AB16=""),"-",(AB16-Z16)*100/Z16) -> - | AC16: =IF(OR(AB16="",AD16=""),"-",(AD16-AB16)*100/AB16) -> - | AE16: =IF(OR(AD16="",AF16=""),"-",(AF16-AD16)*100/AD16) -> -
A17: Quadril | C17: ='BD tratado'!D15 -> #NAME? | D17: 94 | E17: =IF(OR(D17="",F17=""),"-",(F17-D17)*100/D17) -> -6.3829787 | F17: 88 | G17: =IF(OR(F17="",H17=""),"-",(H17-F17)*100/F17) -> -3.4090909 | H17: 85 | I17: =IF(OR(H17="",J17=""),"-",(J17-H17)*100/H17) -> 1.1764706 | J17: 86 | K17: =IF(OR(J17="",L17=""),"-",(L17-J17)*100/J17) -> 2.9069767 | L17: 88.5 | M17: =IF(OR(L17="",N17=""),"-",(N17-L17)*100/L17) -> -0.56497175 | N17: 88 | O17: =IF(OR(N17="",P17=""),"-",(P17-N17)*100/N17) -> 1.1363636 | P17: 89 | Q17: =IF(OR(P17="",R17=""),"-",(R17-P17)*100/P17) -> 1.1235955 | R17: 90 | S17: =IF(OR(R17="",T17=""),"-",(T17-R17)*100/R17) -> -1.1111111 | T17: 89 | U17: =IF(OR(T17="",V17=""),"-",(V17-T17)*100/T17) -> -0.56179775 | V17: 88.5 | W17: =IF(OR(V17="",X17=""),"-",(X17-V17)*100/V17) -> 0.56497175 | X17: 89 | Y17: =IF(OR(X17="",Z17=""),"-",(Z17-X17)*100/X17) -> 0 | Z17: 89 | AA17: =IF(OR(Z17="",AB17=""),"-",(AB17-Z17)*100/Z17) -> - | AC17: =IF(OR(AB17="",AD17=""),"-",(AD17-AB17)*100/AB17) -> - | AE17: =IF(OR(AD17="",AF17=""),"-",(AF17-AD17)*100/AD17) -> -
A18: Br. Dir. Rel. | C18: ='BD tratado'!D16 -> #NAME? | D18: 26.5 | E18: =IF(OR(D18="",F18=""),"-",(F18-D18)*100/D18) -> 1.8867925 | F18: 27 | G18: =IF(OR(F18="",H18=""),"-",(H18-F18)*100/F18) -> -3.7037037 | H18: 26 | I18: =IF(OR(H18="",J18=""),"-",(J18-H18)*100/H18) -> 0 | J18: 26 | K18: =IF(OR(J18="",L18=""),"-",(L18-J18)*100/J18) -> 6.1538462 | L18: 27.6 | M18: =IF(OR(L18="",N18=""),"-",(N18-L18)*100/L18) -> -2.173913 | N18: 27 | O18: =IF(OR(N18="",P18=""),"-",(P18-N18)*100/N18) -> -1.4814815 | P18: 26.6 | Q18: =IF(OR(P18="",R18=""),"-",(R18-P18)*100/P18) -> 7.1428571 | R18: 28.5 | S18: =IF(OR(R18="",T18=""),"-",(T18-R18)*100/R18) -> -5.2631579 | T18: 27 | U18: =IF(OR(T18="",V18=""),"-",(V18-T18)*100/T18) -> 0.74074074 | V18: 27.2 | W18: =IF(OR(V18="",X18=""),"-",(X18-V18)*100/V18) -> - | Y18: =IF(OR(X18="",Z18=""),"-",(Z18-X18)*100/X18) -> - | AA18: =IF(OR(Z18="",AB18=""),"-",(AB18-Z18)*100/Z18) -> - | AC18: =IF(OR(AB18="",AD18=""),"-",(AD18-AB18)*100/AB18) -> - | AE18: =IF(OR(AD18="",AF18=""),"-",(AF18-AD18)*100/AD18) -> -
A19: Br. Dir. Con. | C19: ='BD tratado'!D17 -> #NAME? | D19: 30 | E19: =IF(OR(D19="",F19=""),"-",(F19-D19)*100/D19) -> 6.6666667 | F19: 32 | G19: =IF(OR(F19="",H19=""),"-",(H19-F19)*100/F19) -> -6.25 | H19: 30 | I19: =IF(OR(H19="",J19=""),"-",(J19-H19)*100/H19) -> 3.3333333 | J19: 31 | K19: =IF(OR(J19="",L19=""),"-",(L19-J19)*100/J19) -> 3.2258065 | L19: 32 | M19: =IF(OR(L19="",N19=""),"-",(N19-L19)*100/L19) -> -3.125 | N19: 31 | O19: =IF(OR(N19="",P19=""),"-",(P19-N19)*100/N19) -> 3.2258065 | P19: 32 | Q19: =IF(OR(P19="",R19=""),"-",(R19-P19)*100/P19) -> 2.5 | R19: 32.8 | S19: =IF(OR(R19="",T19=""),"-",(T19-R19)*100/R19) -> -2.4390244 | T19: 32 | U19: =IF(OR(T19="",V19=""),"-",(V19-T19)*100/T19) -> 0 | V19: 32 | W19: =IF(OR(V19="",X19=""),"-",(X19-V19)*100/V19) -> - | Y19: =IF(OR(X19="",Z19=""),"-",(Z19-X19)*100/X19) -> - | AA19: =IF(OR(Z19="",AB19=""),"-",(AB19-Z19)*100/Z19) -> - | AC19: =IF(OR(AB19="",AD19=""),"-",(AD19-AB19)*100/AB19) -> - | AE19: =IF(OR(AD19="",AF19=""),"-",(AF19-AD19)*100/AD19) -> -
A20: Coxa Dir. | C20: ='BD tratado'!D18 -> #NAME? | D20: 53 | E20: =IF(OR(D20="",F20=""),"-",(F20-D20)*100/D20) -> -3.7735849 | F20: 51 | G20: =IF(OR(F20="",H20=""),"-",(H20-F20)*100/F20) -> -1.9607843 | H20: 50 | I20: =IF(OR(H20="",J20=""),"-",(J20-H20)*100/H20) -> 3 | J20: 51.5 | K20: =IF(OR(J20="",L20=""),"-",(L20-J20)*100/J20) -> 0.97087379 | L20: 52 | M20: =IF(OR(L20="",N20=""),"-",(N20-L20)*100/L20) -> 0 | N20: 52 | O20: =IF(OR(N20="",P20=""),"-",(P20-N20)*100/N20) -> -1.9230769 | P20: 51 | Q20: =IF(OR(P20="",R20=""),"-",(R20-P20)*100/P20) -> 3.9215686 | R20: 53 | S20: =IF(OR(R20="",T20=""),"-",(T20-R20)*100/R20) -> -0.94339623 | T20: 52.5 | U20: =IF(OR(T20="",V20=""),"-",(V20-T20)*100/T20) -> 0.95238095 | V20: 53 | W20: =IF(OR(V20="",X20=""),"-",(X20-V20)*100/V20) -> - | Y20: =IF(OR(X20="",Z20=""),"-",(Z20-X20)*100/X20) -> - | AA20: =IF(OR(Z20="",AB20=""),"-",(AB20-Z20)*100/Z20) -> - | AC20: =IF(OR(AB20="",AD20=""),"-",(AD20-AB20)*100/AB20) -> - | AE20: =IF(OR(AD20="",AF20=""),"-",(AF20-AD20)*100/AD20) -> -
A21: Perna Dir. | C21: ='BD tratado'!D19 -> #NAME? | D21: 39.3 | E21: =IF(OR(D21="",F21=""),"-",(F21-D21)*100/D21) -> -3.307888 | F21: 38 | G21: =IF(OR(F21="",H21=""),"-",(H21-F21)*100/F21) -> -1.3157895 | H21: 37.5 | I21: =IF(OR(H21="",J21=""),"-",(J21-H21)*100/H21) -> -1.3333333 | J21: 37 | K21: =IF(OR(J21="",L21=""),"-",(L21-J21)*100/J21) -> 2.7027027 | L21: 38 | M21: =IF(OR(L21="",N21=""),"-",(N21-L21)*100/L21) -> 2.6315789 | N21: 39 | O21: =IF(OR(N21="",P21=""),"-",(P21-N21)*100/N21) -> -5.1282051 | P21: 37 | Q21: =IF(OR(P21="",R21=""),"-",(R21-P21)*100/P21) -> 4.3243243 | R21: 38.6 | S21: =IF(OR(R21="",T21=""),"-",(T21-R21)*100/R21) -> -1.5544041 | T21: 38 | U21: =IF(OR(T21="",V21=""),"-",(V21-T21)*100/T21) -> 0 | V21: 38 | W21: =IF(OR(V21="",X21=""),"-",(X21-V21)*100/V21) -> - | Y21: =IF(OR(X21="",Z21=""),"-",(Z21-X21)*100/X21) -> - | AA21: =IF(OR(Z21="",AB21=""),"-",(AB21-Z21)*100/Z21) -> - | AC21: =IF(OR(AB21="",AD21=""),"-",(AD21-AB21)*100/AB21) -> - | AE21: =IF(OR(AD21="",AF21=""),"-",(AF21-AD21)*100/AD21) -> -
A22: Br. Esq. Rel. | C22: ='BD tratado'!D20 -> #NAME? | D22: 26.5 | E22: =IF(OR(D22="",F22=""),"-",(F22-D22)*100/D22) -> 1.8867925 | F22: 27 | G22: =IF(OR(F22="",H22=""),"-",(H22-F22)*100/F22) -> -3.7037037 | H22: 26 | I22: =IF(OR(H22="",J22=""),"-",(J22-H22)*100/H22) -> 0 | J22: 26 | K22: =IF(OR(J22="",L22=""),"-",(L22-J22)*100/J22) -> 3.8461538 | L22: 27 | M22: =IF(OR(L22="",N22=""),"-",(N22-L22)*100/L22) -> -1.8518519 | N22: 26.5 | O22: =IF(OR(N22="",P22=""),"-",(P22-N22)*100/N22) -> 1.8867925 | P22: 27 | Q22: =IF(OR(P22="",R22=""),"-",(R22-P22)*100/P22) -> 3.7037037 | R22: 28 | S22: =IF(OR(R22="",T22=""),"-",(T22-R22)*100/R22) -> -5.3571429 | T22: 26.5 | U22: =IF(OR(T22="",V22=""),"-",(V22-T22)*100/T22) -> 0.75471698 | V22: 26.7 | W22: =IF(OR(V22="",X22=""),"-",(X22-V22)*100/V22) -> - | Y22: =IF(OR(X22="",Z22=""),"-",(Z22-X22)*100/X22) -> - | AA22: =IF(OR(Z22="",AB22=""),"-",(AB22-Z22)*100/Z22) -> - | AC22: =IF(OR(AB22="",AD22=""),"-",(AD22-AB22)*100/AB22) -> - | AE22: =IF(OR(AD22="",AF22=""),"-",(AF22-AD22)*100/AD22) -> -
A23: Br. Esq. Con. | C23: ='BD tratado'!D21 -> #NAME? | D23: 30 | E23: =IF(OR(D23="",F23=""),"-",(F23-D23)*100/D23) -> 3.3333333 | F23: 31 | G23: =IF(OR(F23="",H23=""),"-",(H23-F23)*100/F23) -> -3.2258065 | H23: 30 | I23: =IF(OR(H23="",J23=""),"-",(J23-H23)*100/H23) -> -1.6666667 | J23: 29.5 | K23: =IF(OR(J23="",L23=""),"-",(L23-J23)*100/J23) -> 5.0847458 | L23: 31 | M23: =IF(OR(L23="",N23=""),"-",(N23-L23)*100/L23) -> -3.2258065 | N23: 30 | O23: =IF(OR(N23="",P23=""),"-",(P23-N23)*100/N23) -> 5 | P23: 31.5 | Q23: =IF(OR(P23="",R23=""),"-",(R23-P23)*100/P23) -> 1.5873016 | R23: 32 | S23: =IF(OR(R23="",T23=""),"-",(T23-R23)*100/R23) -> -1.5625 | T23: 31.5 | U23: =IF(OR(T23="",V23=""),"-",(V23-T23)*100/T23) -> -1.5873016 | V23: 31 | W23: =IF(OR(V23="",X23=""),"-",(X23-V23)*100/V23) -> - | Y23: =IF(OR(X23="",Z23=""),"-",(Z23-X23)*100/X23) -> - | AA23: =IF(OR(Z23="",AB23=""),"-",(AB23-Z23)*100/Z23) -> - | AC23: =IF(OR(AB23="",AD23=""),"-",(AD23-AB23)*100/AB23) -> - | AE23: =IF(OR(AD23="",AF23=""),"-",(AF23-AD23)*100/AD23) -> -
A24: Coxa Esq. | C24: ='BD tratado'!D22 -> #NAME? | D24: 53.3 | E24: =IF(OR(D24="",F24=""),"-",(F24-D24)*100/D24) -> -3.3771107 | F24: 51.5 | G24: =IF(OR(F24="",H24=""),"-",(H24-F24)*100/F24) -> -2.9126214 | H24: 50 | I24: =IF(OR(H24="",J24=""),"-",(J24-H24)*100/H24) -> 4 | J24: 52 | K24: =IF(OR(J24="",L24=""),"-",(L24-J24)*100/J24) -> 1.9230769 | L24: 53 | M24: =IF(OR(L24="",N24=""),"-",(N24-L24)*100/L24) -> -1.8867925 | N24: 52 | O24: =IF(OR(N24="",P24=""),"-",(P24-N24)*100/N24) -> -1.9230769 | P24: 51 | Q24: =IF(OR(P24="",R24=""),"-",(R24-P24)*100/P24) -> 3.9215686 | R24: 53 | S24: =IF(OR(R24="",T24=""),"-",(T24-R24)*100/R24) -> 0 | T24: 53 | U24: =IF(OR(T24="",V24=""),"-",(V24-T24)*100/T24) -> 0.94339623 | V24: 53.5 | W24: =IF(OR(V24="",X24=""),"-",(X24-V24)*100/V24) -> - | Y24: =IF(OR(X24="",Z24=""),"-",(Z24-X24)*100/X24) -> - | AA24: =IF(OR(Z24="",AB24=""),"-",(AB24-Z24)*100/Z24) -> - | AC24: =IF(OR(AB24="",AD24=""),"-",(AD24-AB24)*100/AB24) -> - | AE24: =IF(OR(AD24="",AF24=""),"-",(AF24-AD24)*100/AD24) -> -
A25: Perna Esq. | C25: ='BD tratado'!D23 -> #NAME? | D25: 39 | E25: =IF(OR(D25="",F25=""),"-",(F25-D25)*100/D25) -> -3.8461538 | F25: 37.5 | G25: =IF(OR(F25="",H25=""),"-",(H25-F25)*100/F25) -> -1.3333333 | H25: 37 | I25: =IF(OR(H25="",J25=""),"-",(J25-H25)*100/H25) -> 0.54054054 | J25: 37.2 | K25: =IF(OR(J25="",L25=""),"-",(L25-J25)*100/J25) -> 2.1505376 | L25: 38 | M25: =IF(OR(L25="",N25=""),"-",(N25-L25)*100/L25) -> 2.6315789 | N25: 39 | O25: =IF(OR(N25="",P25=""),"-",(P25-N25)*100/N25) -> -5.1282051 | P25: 37 | Q25: =IF(OR(P25="",R25=""),"-",(R25-P25)*100/P25) -> 5.4054054 | R25: 39 | S25: =IF(OR(R25="",T25=""),"-",(T25-R25)*100/R25) -> -2.0512821 | T25: 38.2 | U25: =IF(OR(T25="",V25=""),"-",(V25-T25)*100/T25) -> -1.8324607 | V25: 37.5 | W25: =IF(OR(V25="",X25=""),"-",(X25-V25)*100/V25) -> - | Y25: =IF(OR(X25="",Z25=""),"-",(Z25-X25)*100/X25) -> - | AA25: =IF(OR(Z25="",AB25=""),"-",(AB25-Z25)*100/Z25) -> - | AC25: =IF(OR(AB25="",AD25=""),"-",(AD25-AB25)*100/AB25) -> - | AE25: =IF(OR(AD25="",AF25=""),"-",(AF25-AD25)*100/AD25) -> -
A26: Dobra Cutânea e TMB
A27: D.C. Tricipital | C27: ='BD tratado'!D25 -> #NAME? | D27: 9.6 | E27: =IF(OR(D27="",F27=""),"-",(F27-D27)*100/D27) -> -56.25 | F27: 4.2 | G27: =IF(OR(F27="",H27=""),"-",(H27-F27)*100/F27) -> -4.7619048 | H27: 4 | I27: =IF(OR(H27="",J27=""),"-",(J27-H27)*100/H27) -> -5 | J27: 3.8 | K27: =IF(OR(J27="",L27=""),"-",(L27-J27)*100/J27) -> 5.2631579 | L27: 4 | M27: =IF(OR(L27="",N27=""),"-",(N27-L27)*100/L27) -> -20 | N27: 3.2 | O27: =IF(OR(N27="",P27=""),"-",(P27-N27)*100/N27) -> 0 | P27: 3.2 | Q27: =IF(OR(P27="",R27=""),"-",(R27-P27)*100/P27) -> 6.25 | R27: 3.4 | S27: =IF(OR(R27="",T27=""),"-",(T27-R27)*100/R27) -> 0 | T27: 3.4 | U27: =IF(OR(T27="",V27=""),"-",(V27-T27)*100/T27) -> 0 | V27: 3.4 | W27: =IF(OR(V27="",X27=""),"-",(X27-V27)*100/V27) -> -11.764706 | X27: 3 | Y27: =IF(OR(X27="",Z27=""),"-",(Z27-X27)*100/X27) -> 13.333333 | Z27: 3.4 | AA27: =IF(OR(Z27="",AB27=""),"-",(AB27-Z27)*100/Z27) -> - | AC27: =IF(OR(AB27="",AD27=""),"-",(AD27-AB27)*100/AB27) -> - | AE27: =IF(OR(AD27="",AF27=""),"-",(AF27-AD27)*100/AD27) -> -
A28: D.C. Subescapular | C28: ='BD tratado'!D26 -> #NAME? | D28: 29 | E28: =IF(OR(D28="",F28=""),"-",(F28-D28)*100/D28) -> -40.689655 | F28: 17.2 | G28: =IF(OR(F28="",H28=""),"-",(H28-F28)*100/F28) -> -40.116279 | H28: 10.3 | I28: =IF(OR(H28="",J28=""),"-",(J28-H28)*100/H28) -> -10.679612 | J28: 9.2 | K28: =IF(OR(J28="",L28=""),"-",(L28-J28)*100/J28) -> 41.304348 | L28: 13 | M28: =IF(OR(L28="",N28=""),"-",(N28-L28)*100/L28) -> -20 | N28: 10.4 | O28: =IF(OR(N28="",P28=""),"-",(P28-N28)*100/N28) -> 0 | P28: 10.4 | Q28: =IF(OR(P28="",R28=""),"-",(R28-P28)*100/P28) -> 45.192308 | R28: 15.1 | S28: =IF(OR(R28="",T28=""),"-",(T28-R28)*100/R28) -> -6.6225166 | T28: 14.1 | U28: =IF(OR(T28="",V28=""),"-",(V28-T28)*100/T28) -> -12.056738 | V28: 12.4 | W28: =IF(OR(V28="",X28=""),"-",(X28-V28)*100/V28) -> -11.290323 | X28: 11 | Y28: =IF(OR(X28="",Z28=""),"-",(Z28-X28)*100/X28) -> 12.727273 | Z28: 12.4 | AA28: =IF(OR(Z28="",AB28=""),"-",(AB28-Z28)*100/Z28) -> - | AC28: =IF(OR(AB28="",AD28=""),"-",(AD28-AB28)*100/AB28) -> - | AE28: =IF(OR(AD28="",AF28=""),"-",(AF28-AD28)*100/AD28) -> -
A29: D.C. Suprailíaca | C29: ='BD tratado'!D27 -> #NAME? | D29: 11.4 | E29: =IF(OR(D29="",F29=""),"-",(F29-D29)*100/D29) -> -60.526316 | F29: 4.5 | G29: =IF(OR(F29="",H29=""),"-",(H29-F29)*100/F29) -> -8.8888889 | H29: 4.1 | I29: =IF(OR(H29="",J29=""),"-",(J29-H29)*100/H29) -> -4.8780488 | J29: 3.9 | K29: =IF(OR(J29="",L29=""),"-",(L29-J29)*100/J29) -> 15.384615 | L29: 4.5 | M29: =IF(OR(L29="",N29=""),"-",(N29-L29)*100/L29) -> -13.333333 | N29: 3.9 | O29: =IF(OR(N29="",P29=""),"-",(P29-N29)*100/N29) -> -2.5641026 | P29: 3.8 | Q29: =IF(OR(P29="",R29=""),"-",(R29-P29)*100/P29) -> 26.315789 | R29: 4.8 | S29: =IF(OR(R29="",T29=""),"-",(T29-R29)*100/R29) -> -4.1666667 | T29: 4.6 | U29: =IF(OR(T29="",V29=""),"-",(V29-T29)*100/T29) -> -6.5217391 | V29: 4.3 | W29: =IF(OR(V29="",X29=""),"-",(X29-V29)*100/V29) -> -2.3255814 | X29: 4.2 | Y29: =IF(OR(X29="",Z29=""),"-",(Z29-X29)*100/X29) -> -4.7619048 | Z29: 4 | AA29: =IF(OR(Z29="",AB29=""),"-",(AB29-Z29)*100/Z29) -> - | AC29: =IF(OR(AB29="",AD29=""),"-",(AD29-AB29)*100/AB29) -> - | AE29: =IF(OR(AD29="",AF29=""),"-",(AF29-AD29)*100/AD29) -> -
A30: D.C. Abdominal | C30: ='BD tratado'!D28 -> #NAME? | D30: 32 | E30: =IF(OR(D30="",F30=""),"-",(F30-D30)*100/D30) -> -57.5 | F30: 13.6 | G30: =IF(OR(F30="",H30=""),"-",(H30-F30)*100/F30) -> -29.411765 | H30: 9.6 | I30: =IF(OR(H30="",J30=""),"-",(J30-H30)*100/H30) -> -6.25 | J30: 9 | K30: =IF(OR(J30="",L30=""),"-",(L30-J30)*100/J30) -> 45.555556 | L30: 13.1 | M30: =IF(OR(L30="",N30=""),"-",(N30-L30)*100/L30) -> -38.931298 | N30: 8 | O30: =IF(OR(N30="",P30=""),"-",(P30-N30)*100/N30) -> 6.25 | P30: 8.5 | Q30: =IF(OR(P30="",R30=""),"-",(R30-P30)*100/P30) -> 52.941176 | R30: 13 | S30: =IF(OR(R30="",T30=""),"-",(T30-R30)*100/R30) -> -2.3076923 | T30: 12.7 | U30: =IF(OR(T30="",V30=""),"-",(V30-T30)*100/T30) -> 0.78740157 | V30: 12.8 | W30: =IF(OR(V30="",X30=""),"-",(X30-V30)*100/V30) -> -22.65625 | X30: 9.9 | Y30: =IF(OR(X30="",Z30=""),"-",(Z30-X30)*100/X30) -> -5.0505051 | Z30: 9.4 | AA30: =IF(OR(Z30="",AB30=""),"-",(AB30-Z30)*100/Z30) -> - | AC30: =IF(OR(AB30="",AD30=""),"-",(AD30-AB30)*100/AB30) -> - | AE30: =IF(OR(AD30="",AF30=""),"-",(AF30-AD30)*100/AD30) -> -
A31: D.C. Coxa | C31: ='BD tratado'!D29 -> #NAME? | D31: 7.7 | E31: =IF(OR(D31="",F31=""),"-",(F31-D31)*100/D31) -> -25.974026 | F31: 5.7 | G31: =IF(OR(F31="",H31=""),"-",(H31-F31)*100/F31) -> -29.824561 | H31: 4 | I31: =IF(OR(H31="",J31=""),"-",(J31-H31)*100/H31) -> 5 | J31: 4.2 | K31: =IF(OR(J31="",L31=""),"-",(L31-J31)*100/J31) -> 14.285714 | L31: 4.8 | M31: =IF(OR(L31="",N31=""),"-",(N31-L31)*100/L31) -> -2.0833333 | N31: 4.7 | O31: =IF(OR(N31="",P31=""),"-",(P31-N31)*100/N31) -> -25.531915 | P31: 3.5 | Q31: =IF(OR(P31="",R31=""),"-",(R31-P31)*100/P31) -> 40 | R31: 4.9 | S31: =IF(OR(R31="",T31=""),"-",(T31-R31)*100/R31) -> -4.0816327 | T31: 4.7 | U31: =IF(OR(T31="",V31=""),"-",(V31-T31)*100/T31) -> 6.3829787 | V31: 5 | W31: =IF(OR(V31="",X31=""),"-",(X31-V31)*100/V31) -> -4 | X31: 4.8 | Y31: =IF(OR(X31="",Z31=""),"-",(Z31-X31)*100/X31) -> -12.5 | Z31: 4.2 | AA31: =IF(OR(Z31="",AB31=""),"-",(AB31-Z31)*100/Z31) -> - | AC31: =IF(OR(AB31="",AD31=""),"-",(AD31-AB31)*100/AB31) -> - | AE31: =IF(OR(AD31="",AF31=""),"-",(AF31-AD31)*100/AD31) -> -
A32: Total de Dobras* | C32: ='BD tratado'!D30 -> #NAME? | D32: =IF(COUNTBLANK(D27:D31)>2,"",SUM(D27:D31)) -> 89.7 | E32: =IF(OR(D32="",F32=""),"-",(F32-D32)*100/D32) -> -49.60981 | F32: =IF(COUNTBLANK(F27:F31)>2,"",SUM(F27:F31)) -> 45.2 | G32: =IF(OR(F32="",H32=""),"-",(H32-F32)*100/F32) -> -29.20354 | H32: =IF(COUNTBLANK(H27:H31)>2,"",SUM(H27:H31)) -> 32 | I32: =IF(OR(H32="",J32=""),"-",(J32-H32)*100/H32) -> -5.9375 | J32: =IF(COUNTBLANK(J27:J31)>2,"",SUM(J27:J31)) -> 30.1 | K32: =IF(OR(J32="",L32=""),"-",(L32-J32)*100/J32) -> 30.89701 | L32: =IF(COUNTBLANK(L27:L31)>2,"",SUM(L27:L31)) -> 39.4 | M32: =IF(OR(L32="",N32=""),"-",(N32-L32)*100/L32) -> -23.350254 | N32: =IF(COUNTBLANK(N27:N31)>2,"",SUM(N27:N31)) -> 30.2 | O32: =IF(OR(N32="",P32=""),"-",(P32-N32)*100/N32) -> -2.6490066 | P32: =IF(COUNTBLANK(P27:P31)>2,"",SUM(P27:P31)) -> 29.4 | Q32: =IF(OR(P32="",R32=""),"-",(R32-P32)*100/P32) -> 40.136054 | R32: =IF(COUNTBLANK(R27:R31)>2,"",SUM(R27:R31)) -> 41.2 | S32: =IF(OR(R32="",T32=""),"-",(T32-R32)*100/R32) -> -4.1262136 | T32: =IF(COUNTBLANK(T27:T31)>2,"",SUM(T27:T31)) -> 39.5 | U32: =IF(OR(T32="",V32=""),"-",(V32-T32)*100/T32) -> -4.0506329 | V32: =IF(COUNTBLANK(V27:V31)>2,"",SUM(V27:V31)) -> 37.9 | W32: =IF(OR(V32="",X32=""),"-",(X32-V32)*100/V32) -> -13.192612 | X32: =IF(COUNTBLANK(X27:X31)>2,"",SUM(X27:X31)) -> 32.9 | Y32: =IF(OR(X32="",Z32=""),"-",(Z32-X32)*100/X32) -> 1.5197568 | Z32: =IF(COUNTBLANK(Z27:Z31)>2,"",SUM(Z27:Z31)) -> 33.4 | AA32: =IF(OR(Z32="",AB32=""),"-",(AB32-Z32)*100/Z32) -> - | AB32: =IF(COUNTBLANK(AB27:AB31)>2,"",SUM(AB27:AB31)) | AC32: =IF(OR(AB32="",AD32=""),"-",(AD32-AB32)*100/AB32) -> - | AD32: =IF(COUNTBLANK(AD27:AD31)>2,"",SUM(AD27:AD31)) | AE32: =IF(OR(AD32="",AF32=""),"-",(AF32-AD32)*100/AD32) -> - | AF32: =IF(COUNTBLANK(AF27:AF31)>2,"",SUM(AF27:AF31))
A33: % Gordura | C33: ='BD tratado'!D31 -> #NAME? | D33: =IF(D32,IF($K$1="Feminino",(4.95/(1.1665-(0.07063*(LOG10(D28+D29+D31))))-4.5)*100,((4.95/(1.17136-(0.06706*(LOG10(D27+D29+D30))))-4.5))*100),"") -> 18.869855 | E33: =IF(OR(D33="",F33=""),"-",(F33-D33)*100/D33) -> -57.956079 | F33: =IF(F32,IF($K$1="Feminino",(4.95/(1.1665-(0.07063*(LOG10(F28+F29+F31))))-4.5)*100,((4.95/(1.17136-(0.06706*(LOG10(F27+F29+F30))))-4.5))*100),"") -> 7.9336269 | G33: =IF(OR(F33="",H33=""),"-",(H33-F33)*100/F33) -> -35.705451 | H33: =IF(H32,IF($K$1="Feminino",(4.95/(1.1665-(0.07063*(LOG10(H28+H29+H31))))-4.5)*100,((4.95/(1.17136-(0.06706*(LOG10(H27+H29+H30))))-4.5))*100),"") -> 5.1008896 | I33: =IF(OR(H33="",J33=""),"-",(J33-H33)*100/H33) -> -13.871719 | J33: =IF(J32,IF($K$1="Feminino",(4.95/(1.1665-(0.07063*(LOG10(J28+J29+J31))))-4.5)*100,((4.95/(1.17136-(0.06706*(LOG10(J27+J29+J30))))-4.5))*100),"") -> 4.3933085 | K33: =IF(OR(J33="",L33=""),"-",(L33-J33)*100/J33) -> 71.63515 | L33: =IF(L32,IF($K$1="Feminino",(4.95/(1.1665-(0.07063*(LOG10(L28+L29+L31))))-4.5)*100,((4.95/(1.17136-(0.06706*(LOG10(L27+L29+L30))))-4.5))*100),"") -> 7.5404617 | M33: =IF(OR(L33="",N33=""),"-",(N33-L33)*100/L33) -> -57.918814 | N33: =IF(N32,IF($K$1="Feminino",(4.95/(1.1665-(0.07063*(LOG10(N28+N29+N31))))-4.5)*100,((4.95/(1.17136-(0.06706*(LOG10(N27+N29+N30))))-4.5))*100),"") -> 3.1731157 | O33: =IF(OR(N33="",P33=""),"-",(P33-N33)*100/N33) -> 9.9627947 | P33: =IF(P32,IF($K$1="Feminino",(4.95/(1.1665-(0.07063*(LOG10(P28+P29+P31))))-4.5)*100,((4.95/(1.17136-(0.06706*(LOG10(P27+P29+P30))))-4.5))*100),"") -> 3.4892467 | Q33: =IF(OR(P33="",R33=""),"-",(R33-P33)*100/P33) -> 109.51079 | R33: =IF(R32,IF($K$1="Feminino",(4.95/(1.1665-(0.07063*(LOG10(R28+R29+R31))))-4.5)*100,((4.95/(1.17136-(0.06706*(LOG10(R27+R29+R30))))-4.5))*100),"") -> 7.3103482 | S33: =IF(OR(R33="",T33=""),"-",(T33-R33)*100/R33) -> -4.0147124 | T33: =IF(T32,IF($K$1="Feminino",(4.95/(1.1665-(0.07063*(LOG10(T28+T29+T31))))-4.5)*100,((4.95/(1.17136-(0.06706*(LOG10(T27+T29+T30))))-4.5))*100),"") -> 7.0168588 | U33: =IF(OR(T33="",V33=""),"-",(V33-T33)*100/T33) -> -1.6998758 | V33: =IF(V32,IF($K$1="Feminino",(4.95/(1.1665-(0.07063*(LOG10(V28+V29+V31))))-4.5)*100,((4.95/(1.17136-(0.06706*(LOG10(V27+V29+V30))))-4.5))*100),"") -> 6.8975809 | W33: =IF(OR(V33="",X33=""),"-",(X33-V33)*100/V33) -> -32.135166 | X33: =IF(X32,IF($K$1="Feminino",(4.95/(1.1665-(0.07063*(LOG10(X28+X29+X31))))-4.5)*100,((4.95/(1.17136-(0.06706*(LOG10(X27+X29+X30))))-4.5))*100),"") -> 4.6810318 | Y33: =IF(OR(X33="",Z33=""),"-",(Z33-X33)*100/X33) -> -4.596974 | Z33: =IF(Z32,IF($K$1="Feminino",(4.95/(1.1665-(0.07063*(LOG10(Z28+Z29+Z31))))-4.5)*100,((4.95/(1.17136-(0.06706*(LOG10(Z27+Z29+Z30))))-4.5))*100),"") -> 4.465846 | AA33: =IF(OR(Z33="",AB33=""),"-",(AB33-Z33)*100/Z33) -> #VALUE! | AB33: =IF(AB32,IF($K$1="Feminino",(4.95/(1.1665-(0.07063*(LOG10(AB28+AB29+AB31))))-4.5)*100,((4.95/(1.17136-(0.06706*(LOG10(AB27+AB29+AB30))))-4.5))*100),"") -> #VALUE! | AC33: =IF(OR(AB33="",AD33=""),"-",(AD33-AB33)*100/AB33) -> #VALUE! | AD33: =IF(AD32,IF($K$1="Feminino",(4.95/(1.1665-(0.07063*(LOG10(AD28+AD29+AD31))))-4.5)*100,((4.95/(1.17136-(0.06706*(LOG10(AD27+AD29+AD30))))-4.5))*100),"") -> #VALUE! | AE33: =IF(OR(AD33="",AF33=""),"-",(AF33-AD33)*100/AD33) -> #VALUE! | AF33: =IF(AF32,IF($K$1="Feminino",(4.95/(1.1665-(0.07063*(LOG10(AF28+AF29+AF31))))-4.5)*100,((4.95/(1.17136-(0.06706*(LOG10(AF27+AF29+AF30))))-4.5))*100),"") -> #VALUE!
A34: Gordura Absoluta (kg) | C34: ='BD tratado'!D32 -> #NAME? | D34: =IF(D33,D33*D10/100,"") -> 14.28448 | E34: =IF(OR(D34="",F34=""),"-",(F34-D34)*100/D34) -> -62.232673 | F34: =IF(F33,F33*F10/100,"") -> 5.3948663 | G34: =IF(OR(F34="",H34=""),"-",(H34-F34)*100/F34) -> -40.716644 | H34: =IF(H33,H33*H10/100,"") -> 3.1982578 | I34: =IF(OR(H34="",J34=""),"-",(J34-H34)*100/H34) -> -10.849674 | J34: =IF(J33,J33*J10/100,"") -> 2.8512572 | K34: =IF(OR(J34="",L34=""),"-",(L34-J34)*100/J34) -> 79.040056 | L34: =IF(L33,L33*L10/100,"") -> 5.1048926 | M34: =IF(OR(L34="",N34=""),"-",(N34-L34)*100/L34) -> -57.980972 | N34: =IF(N33,N33*N10/100,"") -> 2.1450262 | O34: =IF(OR(N34="",P34=""),"-",(P34-N34)*100/N34) -> 9.9627947 | P34: =IF(P33,P33*P10/100,"") -> 2.3587308 | Q34: =IF(OR(P34="",R34=""),"-",(R34-P34)*100/P34) -> 119.11853 | R34: =IF(R33,R33*R10/100,"") -> 5.1684162 | S34: =IF(OR(R34="",T34=""),"-",(T34-R34)*100/R34) -> -6.3227038 | T34: =IF(T33,T33*T10/100,"") -> 4.8416325 | U34: =IF(OR(T34="",V34=""),"-",(V34-T34)*100/T34) -> -2.2697316 | V34: =IF(V33,V33*V10/100,"") -> 4.7317405 | W34: =IF(OR(V34="",X34=""),"-",(X34-V34)*100/V34) -> -33.718019 | X34: =IF(X33,X33*X10/100,"") -> 3.1362913 | Y34: =IF(OR(X34="",Z34=""),"-",(Z34-X34)*100/X34) -> -0.3251967 | Z34: =IF(Z33,Z33*Z10/100,"") -> 3.1260922 | AA34: =IF(OR(Z34="",AB34=""),"-",(AB34-Z34)*100/Z34) -> #VALUE! | AB34: =IF(AB33,AB33*AB10/100,"") -> #VALUE! | AC34: =IF(OR(AB34="",AD34=""),"-",(AD34-AB34)*100/AB34) -> #VALUE! | AD34: =IF(AD33,AD33*AD10/100,"") -> #VALUE! | AE34: =IF(OR(AD34="",AF34=""),"-",(AF34-AD34)*100/AD34) -> #VALUE! | AF34: =IF(AF33,AF33*AF10/100,"") -> #VALUE!
A35: Massa Magra (kg) | C35: ='BD tratado'!D33 -> #NAME? | D35: =IF(D34,D10-D34,"") -> 61.41552 | E35: =IF(OR(D35="",F35=""),"-",(F35-D35)*100/D35) -> 1.9369921 | F35: =IF(F34,F10-F34,"") -> 62.605134 | G35: =IF(OR(F35="",H35=""),"-",(H35-F35)*100/F35) -> -4.9570879 | H35: =IF(H34,H10-H34,"") -> 59.501742 | I35: =IF(OR(H35="",J35=""),"-",(J35-H35)*100/H35) -> 4.2805478 | J35: =IF(J34,J10-J34,"") -> 62.048743 | K35: =IF(OR(J35="",L35=""),"-",(L35-J35)*100/J35) -> 0.88054108 | L35: =IF(L34,L10-L34,"") -> 62.595107 | M35: =IF(OR(L35="",N35=""),"-",(N35-L35)*100/L35) -> 4.5688337 | N35: =IF(N34,N10-N34,"") -> 65.454974 | O35: =IF(OR(N35="",P35=""),"-",(P35-N35)*100/N35) -> -0.32649094 | P35: =IF(P34,P10-P34,"") -> 65.241269 | Q35: =IF(OR(P35="",R35=""),"-",(R35-P35)*100/P35) -> 0.44498612 | R35: =IF(R34,R10-R34,"") -> 65.531584 | S35: =IF(OR(R35="",T35=""),"-",(T35-R35)*100/R35) -> -2.0955031 | T35: =IF(T34,T10-T34,"") -> 64.158367 | U35: =IF(OR(T35="",V35=""),"-",(V35-T35)*100/T35) -> -0.45217475 | V35: =IF(V34,V10-V34,"") -> 63.86826 | W35: =IF(OR(V35="",X35=""),"-",(X35-V35)*100/V35) -> -0.0071253396 | X35: =IF(X34,X10-X34,"") -> 63.863709 | Y35: =IF(OR(X35="",Z35=""),"-",(Z35-X35)*100/X35) -> 4.7134737 | Z35: =IF(Z34,Z10-Z34,"") -> 66.873908 | AA35: =IF(OR(Z35="",AB35=""),"-",(AB35-Z35)*100/Z35) -> #VALUE! | AB35: =IF(AB34,AB10-AB34,"") -> #VALUE! | AC35: =IF(OR(AB35="",AD35=""),"-",(AD35-AB35)*100/AB35) -> #VALUE! | AD35: =IF(AD34,AD10-AD34,"") -> #VALUE! | AE35: =IF(OR(AD35="",AF35=""),"-",(AF35-AD35)*100/AD35) -> #VALUE! | AF35: =IF(AF34,AF10-AF34,"") -> #VALUE!
A36: Massa Muscular (kg; bioimpedância) | C36: ='BD tratado'!D34 -> #NAME? | D36: 31.1 | E36: =IF(OR(D36="",F36=""),"-",(F36-D36)*100/D36) -> 1.2861736 | F36: 31.5 | G36: =IF(OR(F36="",H36=""),"-",(H36-F36)*100/F36) -> -1.9047619 | H36: 30.9 | I36: =IF(OR(H36="",J36=""),"-",(J36-H36)*100/H36) -> 8.4142395 | J36: 33.5 | K36: =IF(OR(J36="",L36=""),"-",(L36-J36)*100/J36) -> 0.29850746 | L36: 33.6 | M36: =IF(OR(L36="",N36=""),"-",(N36-L36)*100/L36) -> 1.4880952 | N36: 34.1 | O36: =IF(OR(N36="",P36=""),"-",(P36-N36)*100/N36) -> 0 | P36: 34.1 | Q36: =IF(OR(P36="",R36=""),"-",(R36-P36)*100/P36) -> 0 | R36: 34.1 | S36: =IF(OR(R36="",T36=""),"-",(T36-R36)*100/R36) -> -2.0527859 | T36: 33.4 | U36: =IF(OR(T36="",V36=""),"-",(V36-T36)*100/T36) -> 2.0958084 | V36: 34.1 | W36: =IF(OR(V36="",X36=""),"-",(X36-V36)*100/V36) -> 0 | X36: 34.1 | Y36: =IF(OR(X36="",Z36=""),"-",(Z36-X36)*100/X36) -> -0.29325513 | Z36: 34 | AA36: =IF(OR(Z36="",AB36=""),"-",(AB36-Z36)*100/Z36) -> - | AC36: =IF(OR(AB36="",AD36=""),"-",(AD36-AB36)*100/AB36) -> - | AE36: =IF(OR(AD36="",AF36=""),"-",(AF36-AD36)*100/AD36) -> -
A37: Nível de Gordura Visceral (ua; bioimpedância) | C37: ='BD tratado'!D35 -> #NAME? | D37: 9 | E37: =IF(OR(D37="",F37=""),"-",(F37-D37)*100/D37) -> -11.111111 | F37: 8 | G37: =IF(OR(F37="",H37=""),"-",(H37-F37)*100/F37) -> -75 | H37: 2 | I37: =IF(OR(H37="",J37=""),"-",(J37-H37)*100/H37) -> -50 | J37: 1 | K37: =IF(OR(J37="",L37=""),"-",(L37-J37)*100/J37) -> 100 | L37: 2 | M37: =IF(OR(L37="",N37=""),"-",(N37-L37)*100/L37) -> 0 | N37: 2 | O37: =IF(OR(N37="",P37=""),"-",(P37-N37)*100/N37) -> 0 | P37: 2 | Q37: =IF(OR(P37="",R37=""),"-",(R37-P37)*100/P37) -> 200 | R37: 6 | S37: =IF(OR(R37="",T37=""),"-",(T37-R37)*100/R37) -> 50 | T37: 9 | U37: =IF(OR(T37="",V37=""),"-",(V37-T37)*100/T37) -> -11.111111 | V37: 8 | W37: =IF(OR(V37="",X37=""),"-",(X37-V37)*100/V37) -> 0 | X37: 8 | Y37: =IF(OR(X37="",Z37=""),"-",(Z37-X37)*100/X37) -> 12.5 | Z37: 9 | AA37: =IF(OR(Z37="",AB37=""),"-",(AB37-Z37)*100/Z37) -> - | AC37: =IF(OR(AB37="",AD37=""),"-",(AD37-AB37)*100/AB37) -> - | AE37: =IF(OR(AD37="",AF37=""),"-",(AF37-AD37)*100/AD37) -> -
A38: Taxa Metabólica Basal (kcal; bioimpedância) | C38: ='BD tratado'!D36 -> #NAME? | E38: =IF(OR(D38="",F38=""),"-",(F38-D38)*100/D38) -> - | G38: =IF(OR(F38="",H38=""),"-",(H38-F38)*100/F38) -> - | I38: =IF(OR(H38="",J38=""),"-",(J38-H38)*100/H38) -> - | K38: =IF(OR(J38="",L38=""),"-",(L38-J38)*100/J38) -> - | M38: =IF(OR(L38="",N38=""),"-",(N38-L38)*100/L38) -> - | O38: =IF(OR(N38="",P38=""),"-",(P38-N38)*100/N38) -> - | P38: 1498 | Q38: =IF(OR(P38="",R38=""),"-",(R38-P38)*100/P38) -> 11.348465 | R38: 1668 | S38: =IF(OR(R38="",T38=""),"-",(T38-R38)*100/R38) -> -1.7386091 | T38: 1639 | U38: =IF(OR(T38="",V38=""),"-",(V38-T38)*100/T38) -> 0 | V38: 1639 | W38: =IF(OR(V38="",X38=""),"-",(X38-V38)*100/V38) -> -2.3184869 | X38: 1601 | Y38: =IF(OR(X38="",Z38=""),"-",(Z38-X38)*100/X38) -> 1.8113679 | Z38: 1630 | AA38: =IF(OR(Z38="",AB38=""),"-",(AB38-Z38)*100/Z38) -> - | AC38: =IF(OR(AB38="",AD38=""),"-",(AD38-AB38)*100/AB38) -> - | AE38: =IF(OR(AD38="",AF38=""),"-",(AF38-AD38)*100/AD38) -> -
A39: Taxa Metabólica Basal (kcal; Harris Benedict) | C39: ='BD tratado'!D37 -> #NAME? | D39: =IF(D10,IF($K$1="Masculino",66.5+(13.75*D10)+(5.003*D11)-(6.775*D7),655.1+(9.563*D10)+(1.85*D11)-(4.676*D7)),"") -> 1639.9184 | E39: =IF(OR(D39="",F39=""),"-",(F39-D39)*100/D39) -> -7.1133051 | F39: =IF(F10,IF($K$1="Masculino",66.5+(13.75*F10)+(5.003*F11)-(6.775*F7),655.1+(9.563*F10)+(1.85*F11)-(4.676*F7)),"") -> 1523.266 | G39: =IF(OR(F39="",H39=""),"-",(H39-F39)*100/F39) -> -4.7841283 | H39: =IF(H10,IF($K$1="Masculino",66.5+(13.75*H10)+(5.003*H11)-(6.775*H7),655.1+(9.563*H10)+(1.85*H11)-(4.676*H7)),"") -> 1450.391 | I39: =IF(OR(H39="",J39=""),"-",(J39-H39)*100/H39) -> 2.0856445 | J39: =IF(J10,IF($K$1="Masculino",66.5+(13.75*J10)+(5.003*J11)-(6.775*J7),655.1+(9.563*J10)+(1.85*J11)-(4.676*J7)),"") -> 1480.641 | K39: =IF(OR(J39="",L39=""),"-",(L39-J39)*100/J39) -> 2.1426531 | L39: =IF(L10,IF($K$1="Masculino",66.5+(13.75*L10)+(5.003*L11)-(6.775*L7),655.1+(9.563*L10)+(1.85*L11)-(4.676*L7)),"") -> 1512.366 | M39: =IF(OR(L39="",N39=""),"-",(N39-L39)*100/L39) -> -0.090917146 | N39: =IF(N10,IF($K$1="Masculino",66.5+(13.75*N10)+(5.003*N11)-(6.775*N7),655.1+(9.563*N10)+(1.85*N11)-(4.676*N7)),"") -> 1510.991 | O39: =IF(OR(N39="",P39=""),"-",(P39-N39)*100/N39) -> -0.44838123 | P39: =IF(P10,IF($K$1="Masculino",66.5+(13.75*P10)+(5.003*P11)-(6.775*P7),655.1+(9.563*P10)+(1.85*P11)-(4.676*P7)),"") -> 1504.216 | Q39: =IF(OR(P39="",R39=""),"-",(R39-P39)*100/P39) -> 2.8337021 | R39: =IF(R10,IF($K$1="Masculino",66.5+(13.75*R10)+(5.003*R11)-(6.775*R7),655.1+(9.563*R10)+(1.85*R11)-(4.676*R7)),"") -> 1546.841 | S39: =IF(OR(R39="",T39=""),"-",(T39-R39)*100/R39) -> -1.9491338 | T39: =IF(T10,IF($K$1="Masculino",66.5+(13.75*T10)+(5.003*T11)-(6.775*T7),655.1+(9.563*T10)+(1.85*T11)-(4.676*T7)),"") -> 1516.691 | U39: =IF(OR(T39="",V39=""),"-",(V39-T39)*100/T39) -> -0.36263154 | V39: =IF(V10,IF($K$1="Masculino",66.5+(13.75*V10)+(5.003*V11)-(6.775*V7),655.1+(9.563*V10)+(1.85*V11)-(4.676*V7)),"") -> 1511.191 | W39: =IF(OR(V39="",X39=""),"-",(X39-V39)*100/V39) -> -1.4558054 | X39: =IF(X10,IF($K$1="Masculino",66.5+(13.75*X10)+(5.003*X11)-(6.775*X7),655.1+(9.563*X10)+(1.85*X11)-(4.676*X7)),"") -> 1489.191 | Y39: =IF(OR(X39="",Z39=""),"-",(Z39-X39)*100/X39) -> 2.7699603 | Z39: =IF(Z10,IF($K$1="Masculino",66.5+(13.75*Z10)+(5.003*Z11)-(6.775*Z7),655.1+(9.563*Z10)+(1.85*Z11)-(4.676*Z7)),"") -> 1530.441 | AA39: =IF(OR(Z39="",AB39=""),"-",(AB39-Z39)*100/Z39) -> - | AB39: =IF(AB10,IF($K$1="Masculino",66.5+(13.75*AB10)+(5.003*AB11)-(6.775*AB7),655.1+(9.563*AB10)+(1.85*AB11)-(4.676*AB7)),"") | AC39: =IF(OR(AB39="",AD39=""),"-",(AD39-AB39)*100/AB39) -> - | AD39: =IF(AD10,IF($K$1="Masculino",66.5+(13.75*AD10)+(5.003*AD11)-(6.775*AD7),655.1+(9.563*AD10)+(1.85*AD11)-(4.676*AD7)),"") | AE39: =IF(OR(AD39="",AF39=""),"-",(AF39-AD39)*100/AD39) -> - | AF39: =IF(AF10,IF($K$1="Masculino",66.5+(13.75*AF10)+(5.003*AF11)-(6.775*AF7),655.1+(9.563*AF10)+(1.85*AF11)-(4.676*AF7)),"")
A40: Taxa Metabólica Basal (kcal; Média) | C40: ='BD tratado'!D38 -> #NAME? | D40: =IF(D39,AVERAGE(D38:D39),"") -> 1639.9184 | E40: =IF(OR(D40="",F40=""),"-",(F40-D40)*100/D40) -> -7.1133051 | F40: =IF(F39,AVERAGE(F38:F39),"") -> 1523.266 | G40: =IF(OR(F40="",H40=""),"-",(H40-F40)*100/F40) -> -4.7841283 | H40: =IF(H39,AVERAGE(H38:H39),"") -> 1450.391 | I40: =IF(OR(H40="",J40=""),"-",(J40-H40)*100/H40) -> 2.0856445 | J40: =IF(J39,AVERAGE(J38:J39),"") -> 1480.641 | K40: =IF(OR(J40="",L40=""),"-",(L40-J40)*100/J40) -> 2.1426531 | L40: =IF(L39,AVERAGE(L38:L39),"") -> 1512.366 | M40: =IF(OR(L40="",N40=""),"-",(N40-L40)*100/L40) -> -0.090917146 | N40: =IF(N39,AVERAGE(N38:N39),"") -> 1510.991 | O40: =IF(OR(N40="",P40=""),"-",(P40-N40)*100/N40) -> -0.65407405 | P40: =IF(P39,AVERAGE(P38:P39),"") -> 1501.108 | Q40: =IF(OR(P40="",R40=""),"-",(R40-P40)*100/P40) -> 7.0822686 | R40: =IF(R39,AVERAGE(R38:R39),"") -> 1607.4205 | S40: =IF(OR(R40="",T40=""),"-",(T40-R40)*100/R40) -> -1.8399044 | T40: =IF(T39,AVERAGE(T38:T39),"") -> 1577.8455 | U40: =IF(OR(T40="",V40=""),"-",(V40-T40)*100/T40) -> -0.17428829 | V40: =IF(V39,AVERAGE(V38:V39),"") -> 1575.0955 | W40: =IF(OR(V40="",X40=""),"-",(X40-V40)*100/V40) -> -1.9046464 | X40: =IF(X39,AVERAGE(X38:X39),"") -> 1545.0955 | Y40: =IF(OR(X40="",Z40=""),"-",(Z40-X40)*100/X40) -> 2.2733223 | Z40: =IF(Z39,AVERAGE(Z38:Z39),"") -> 1580.2205 | AA40: =IF(OR(Z40="",AB40=""),"-",(AB40-Z40)*100/Z40) -> #VALUE! | AB40: =IF(AB39,AVERAGE(AB38:AB39),"") -> #VALUE! | AC40: =IF(OR(AB40="",AD40=""),"-",(AD40-AB40)*100/AB40) -> #VALUE! | AD40: =IF(AD39,AVERAGE(AD38:AD39),"") -> #VALUE! | AE40: =IF(OR(AD40="",AF40=""),"-",(AF40-AD40)*100/AD40) -> #VALUE! | AF40: =IF(AF39,AVERAGE(AF38:AF39),"") -> #VALUE!
...

Sheet Meta calórica
A1: Nome | C1: =Avaliação!B1 -> Claudinei Rogério Gasparoto
A3: Composição Corporal Meta Etapa
A4: Av10 | F4: Valor Atual | I4: Meta Proposta | O4: △%
A5: =OFFSET(BD!$A$2,,MATCH(A4,BD!$B$1:$P$1,0)) -> 45938 | I5: MÍN | L5: MÁX
A6: % Gordura | F6: =OFFSET(BD!$A31,0,MATCH($A$4,BD!$B$1:$P$1,0)) -> 6.8975809 | I6: 7 | L6: 8 | O6: =(((L6+I6)/2)-F6)/F6*100 -> 8.7337739
A7: Gordura Absoluta(kg) | F7: =OFFSET(BD!$A32,0,MATCH($A$4,BD!$B$1:$P$1,0)) -> 4.7317405 | I7: =I6*$I$10/100 -> 4.7795699 | L7: =L6*$I$10/100 -> 5.4623656 | O7: =(((L7+I7)/2)-F7)/F7*100 -> 8.2258792
A8: Massa Magra(kg) | F8: =OFFSET(BD!$A33,0,MATCH($A$4,BD!$B$1:$P$1,0)) -> 63.86826 | I8: 63.5 | L8: 64.5 | O8: =(((L8+I8)/2)-F8)/F8*100 -> 0.2062691
A9: Nível de Gordura Visceral (ua; bioimpedância) | F9: =OFFSET(BD!$A35,0,MATCH($A$4,BD!$B$1:$P$1,0)) -> 8 | I9: 7 | L9: 8 | O9: =(((L9+I9)/2)-F9)/F9*100 -> -6.25
A10: Peso Corporal Total (kg) | F10: =OFFSET(BD!$A8,0,MATCH($A$4,BD!$B$1:$P$1,0)) -> 68.6 | I10: =I8/(1-(I6/100)) -> 68.27957 | L10: =L8/(1-(L6/100)) -> 70.108696 | O10: =(((L10+I10)/2)-F10)/F10*100 -> 0.86608276
A11: Variação máxima de peso saudável (kg) | I11: =IF(Avaliação!$K$1="Masculino",I8/0.9,I8/0.8) -> 70.555556 | L11: =IF(Avaliação!$K$1="Masculino",I8/0.78,I8/0.68) -> 81.410256
J13: Metas:
J15: =IF(I8>F8," ● Desenvolver a ","● Manutenção da ")&"massa magra entre "&ROUND(I8-F8,1)&" e "&ROUND(L8-F8,1)&" kg (~"&ROUND(O8,1)&IF(O8>0,"%▲)","%▼)") -> ● Manutenção da massa magra entre -0,4 e 0,6 kg (~0,2%▲)
J17: =IF(O7<0," ● Reduzir ","● Manter ")&"a gordura absoluta entre "&ABS(ROUND((L7-F7),1))&" e "&ROUND((I7-F7)*-1,1)&" kg (~"&ABS(ROUND(O7,1))&IF(O7<0,"%▼)","%▲)") -> ● Manter a gordura absoluta entre 0,7 e 0 kg (~8,2%▲)
J19: =" Dessa forma, seu percentual de gordura atingirá entre "&I6&" e "&L6&"% (~"&ABS(ROUND(O6,1))&IF(O6<0,"%▼)","%▲)") -> Dessa forma, seu percentual de gordura atingirá entre 7 e 8% (~8,7%▲)
A41: Estudo Calórico Atual
A42: Taxa Metabólica Basal (Haris Benedict; kcal) | F42: ='BD tratado'!C37 -> 1530.441 | I42: Taxa Metabólica Média (kcal) | N42: ='BD tratado'!C38 -> #VALUE!
A44: Taxa Metabólica Basal (Bioimpedância; kcal) | F44: ='BD tratado'!C36 -> 1630
A48: Regra de Bolso | G48: Mínimo | K48: Máximo | O48: Médio
A49: Redução de Peso | G49: =$F$10*20 -> 1372 | K49: =$G$50 -> 1715 | O49: =AVERAGE(G49,K49) -> 1543.5
A50: Manutenção de Peso | G50: =$F$10*25 -> 1715 | K50: =$G$51 -> 2058 | O50: =AVERAGE(G50,K50) -> 1886.5
A51: Ganho de Peso | G51: =$F$10*30 -> 2058 | K51: =$F$10*35 -> 2401 | O51: =AVERAGE(G51,K51) -> 2229.5
A53: Dia da Semana | C53: Segunda | E53: Terça | G53: Quarta | I53: Quinta | K53: Sexta | M53: Sábado | O53: Domingo
A54: TMB | C54: =$N$42 -> #VALUE! | E54: =$N$42 -> #VALUE! | G54: =$N$42 -> #VALUE! | I54: =$N$42 -> #VALUE! | K54: =$N$42 -> #VALUE! | M54: =$N$42 -> #VALUE! | O54: =$N$42 -> #VALUE!
A55: Gasto energético c/ o exercício | C55: =O75 -> 270.1125 | E55: =O76 -> 705.60588 | G55: =O77 -> 1741.9735 | I55: =O78 -> 270.1125 | K55: =O79 -> 270.1125 | M55: =O80 -> 0 | O55: =O81 -> 1741.9735
A58: Outros gastos energéticos
A60: Necessidade Energética | C60: =C54+C55+C58 -> #VALUE! | E60: =E54+E55+E58 -> #VALUE! | G60: =G54+G55+G58 -> #VALUE! | I60: =I54+I55+I58 -> #VALUE! | K60: =K54+K55+K58 -> #VALUE! | M60: =M54+M55+M58 -> #VALUE! | O60: =O54+O55+O58 -> #VALUE!
H63: Total na semana | M63: Média Diária
A64: TMB | H64: =SUM(C54:P54) -> #VALUE! | M64: =H64/7 -> #VALUE!
A65: Gasto energético c/ o exercício | H65: =SUM(C55:P55) -> 4999.8904 | M65: =H65/7 -> 714.27006
A66: Necessidade Energética | H66: =SUM(C60:P61) -> #VALUE! | M66: =H66/7 -> #VALUE!
A67: Aporte Energético Sugerido | H67: =$M$67*7 -> 18295.62 | M67: =$M$88 -> 2613.66
A68: Diferença Absoluta | H68: =H67-H66 -> #VALUE! | M68: =M67-M66 -> #VALUE!
A69: Diferença Relativa | H69: =H68/H66 -> #VALUE! | M69: =M68/M66 -> #VALUE!
A72: Estimativa de gasto energético c/ o exercício
A73: Dia da semana | D73: Volume Treino Resistido (min) | H73: Volume Treino Cíclico (min) | L73: %VO₂Médio | O73: kcal gasto no dia
A75: Segunda | D75: 45 | O75: =(0.0175*$F$10*H75*L75*($C$82/3.5))+(0.0175*$F$10*D75*5) -> 270.1125
A76: Terça | D76: 45 | H76: 30 | L76: 0.7 | O76: =(0.0175*$F$10*H76*L76*($C$82/3.5))+(0.0175*$F$10*D76*5) -> 705.60588
A77: Quarta | H77: 120 | L77: 0.7 | O77: =(0.0175*$F$10*H77*L77*($C$82/3.5))+(0.0175*$F$10*D77*5) -> 1741.9735
A78: Quinta | D78: 45 | O78: =(0.0175*$F$10*H78*L78*($C$82/3.5))+(0.0175*$F$10*D78*5) -> 270.1125
A79: Sexta | D79: 45 | O79: =(0.0175*$F$10*H79*L79*($C$82/3.5))+(0.0175*$F$10*D79*5) -> 270.1125
...

Sheet Metabólica
A1: =Avaliação!B1 -> Claudinei Rogério Gasparoto | E1: Av4 | G1: Av5 | I1: Av6 | K1: Av7 | M1: Av8 | O1: Av9 | Q1: Av10
E2: =IF(E$1="","",OFFSET(Avaliação!$C$3,,MATCH(E$1,Avaliação!$D$2:$AF$2,0))) -> 45078 | G2: =IF(G$1="","",OFFSET(Avaliação!$C$3,,MATCH(G$1,Avaliação!$D$2:$AF$2,0))) -> 45301 | I2: =IF(I$1="","",OFFSET(Avaliação!$C$3,,MATCH(I$1,Avaliação!$D$2:$AF$2,0))) -> 45433 | K2: =IF(K$1="","",OFFSET(Avaliação!$C$3,,MATCH(K$1,Avaliação!$D$2:$AF$2,0))) -> 45611 | M2: =IF(M$1="","",OFFSET(Avaliação!$C$3,,MATCH(M$1,Avaliação!$D$2:$AF$2,0))) -> 45752 | O2: =IF(O$1="","",OFFSET(Avaliação!$C$3,,MATCH(O$1,Avaliação!$D$2:$AF$2,0))) -> 45829 | Q2: =IF(Q$1="","",OFFSET(Avaliação!$C$3,,MATCH(Q$1,Avaliação!$D$2:$AF$2,0))) -> 45938 | S2: =IF(S$1="","",OFFSET(Avaliação!$C$3,,MATCH(S$1,Avaliação!$D$2:$AF$2,0))) | U2: =IF(U$1="","",OFFSET(Avaliação!$C$3,,MATCH(U$1,Avaliação!$D$2:$AF$2,0))) | W2: =IF(W$1="","",OFFSET(Avaliação!$C$3,,MATCH(W$1,Avaliação!$D$2:$AF$2,0))) | Y2: =IF(Y$1="","",OFFSET(Avaliação!$C$3,,MATCH(Y$1,Avaliação!$D$2:$AF$2,0))) | AA2: =IF(AA$1="","",OFFSET(Avaliação!$C$3,,MATCH(AA$1,Avaliação!$D$2:$AF$2,0))) | AC2: =IF(AC$1="","",OFFSET(Avaliação!$C$3,,MATCH(AC$1,Avaliação!$D$2:$AF$2,0))) | AE2: =IF(AE$1="","",OFFSET(Avaliação!$C$3,,MATCH(AE$1,Avaliação!$D$2:$AF$2,0))) | AG2: =IF(AG$1="","",OFFSET(Avaliação!$C$3,,MATCH(AG$1,Avaliação!$D$2:$AF$2,0)))
E3: Pré | F3: Pós | G3: Pré | H3: Pós | I3: Pré | J3: Pós | K3: Pré | L3: Pós | M3: Pré | N3: Pós | O3: Pré | P3: Pós | Q3: Pré | R3: Pós | S3: Pré | T3: Pós | U3: Pré | V3: Pós | W3: Pré | X3: Pós | Y3: Pré | Z3: Pós | AA3: Pré | AB3: Pós | AC3: Pré | AD3: Pós | AE3: Pré | AF3: Pós | AG3: Pré | AH3: Pós
A4: Pressão Arterial Sistólica | E4: 120 | F4: 80 | G4: 140 | H4: 70 | M4: 142 | N4: 212 | O4: 112 | P4: 190 | Q4: 112 | R4: 190
A5: Pressão Arterial Diastólica | G5: 162 | H5: 60 | M5: 63 | N5: 61 | O5: 70 | P5: 76 | Q5: 72 | R5: 70
E6: Fórmula | F6: Ventilometria | G6: Fórmula | H6: Ventilometria | I6: Fórmula | J6: Ventilometria | K6: Fórmula | L6: Ventilometria | M6: Fórmula | N6: Ventilometria | O6: Fórmula | P6: Ventilometria | Q6: Fórmula | R6: Ventilometria | S6: Fórmula | T6: Ventilometria | U6: Fórmula | V6: Ventilometria | W6: Fórmula | X6: Ventilometria | Y6: Fórmula | Z6: Ventilometria | AA6: Fórmula | AB6: Ventilometria | AC6: Fórmula | AD6: Ventilometria | AE6: Fórmula | AF6: Ventilometria | AG6: Fórmula | AH6: Ventilometria
A7: VO₂Max | E7: =_xludf.IFS(E17="","",E15="Teste de Esteira Progressiva",(0.2*(E11*16.66))+((0.9*(E11*16.66))*(OFFSET($B$17,_xludf.MAXIFS($A$17:$A$34,E$17:E$34,">0"),)*1.746/100)+3.5),TRUE(),"-") -> #NAME? | F7: 56.6 | G7: =_xludf.IFS(G17="","",G15="Teste de Esteira Progressiva",(0.2*(G11*16.66))+((0.9*(G11*16.66))*(OFFSET($B$17,_xludf.MAXIFS($A$17:$A$34,G$17:G$34,">0"),)*1.746/100)+3.5),TRUE(),"-") -> #NAME? | H7: 57.4 | I7: =_xludf.IFS(I17="","",I15="Teste de Esteira Progressiva",(0.2*(I11*16.66))+((0.9*(I11*16.66))*(OFFSET($B$17,_xludf.MAXIFS($A$17:$A$34,I$17:I$34,">0"),)*1.746/100)+3.5),TRUE(),"-") -> #NAME? | J7: 60.46 | K7: =_xludf.IFS(K17="","",K15="Teste de Esteira Progressiva",(0.2*(K11*16.66))+((0.9*(K11*16.66))*(OFFSET($B$17,_xludf.MAXIFS($A$17:$A$34,K$17:K$34,">0"),)*1.746/100)+3.5),TRUE(),"-") -> #NAME? | L7: 60.46 | M7: =_xludf.IFS(M17="","",M15="Teste de Esteira Progressiva",(0.2*(M11*16.66))+((0.9*(M11*16.66))*(OFFSET($B$17,_xludf.MAXIFS($A$17:$A$34,M$17:M$34,">0"),)*1.746/100)+3.5),TRUE(),"-") -> #NAME? | N7: 57.44 | O7: =_xludf.IFS(O17="","",O15="Teste de Esteira Progressiva",(0.2*(O11*16.66))+((0.9*(O11*16.66))*(OFFSET($B$17,_xludf.MAXIFS($A$17:$A$34,O$17:O$34,">0"),)*1.746/100)+3.5),TRUE(),"-") -> #NAME? | Q7: =_xludf.IFS(Q17="","",Q15="Teste de Esteira Progressiva",(0.2*(Q11*16.66))+((0.9*(Q11*16.66))*(OFFSET($B$17,_xludf.MAXIFS($A$17:$A$34,Q$17:Q$34,">0"),)*1.746/100)+3.5),TRUE(),"-") -> #NAME? | R7: 60.46 | S7: =_xludf.IFS(S17="","",S15="Teste de Esteira Progressiva",(0.2*(S11*16.66))+((0.9*(S11*16.66))*(OFFSET($B$17,_xludf.MAXIFS($A$17:$A$34,S$17:S$34,">0"),)*1.746/100)+3.5),TRUE(),"-") -> #NAME? | U7: =_xludf.IFS(U17="","",U15="Teste de Esteira Progressiva",(0.2*(U11*16.66))+((0.9*(U11*16.66))*(OFFSET($B$17,_xludf.MAXIFS($A$17:$A$34,U$17:U$34,">0"),)*1.746/100)+3.5),TRUE(),"-") -> #NAME? | W7: =_xludf.IFS(W17="","",W15="Teste de Esteira Progressiva",(0.2*(W11*16.66))+((0.9*(W11*16.66))*(OFFSET($B$17,_xludf.MAXIFS($A$17:$A$34,W$17:W$34,">0"),)*1.746/100)+3.5),TRUE(),"-") -> #NAME? | Y7: =_xludf.IFS(Y17="","",Y15="Teste de Esteira Progressiva",(0.2*(Y11*16.66))+((0.9*(Y11*16.66))*(OFFSET($B$17,_xludf.MAXIFS($A$17:$A$34,Y$17:Y$34,">0"),)*1.746/100)+3.5),TRUE(),"-") -> #NAME? | AA7: =_xludf.IFS(AA17="","",AA15="Teste de Esteira Progressiva",(0.2*(AA11*16.66))+((0.9*(AA11*16.66))*(OFFSET($B$17,_xludf.MAXIFS($A$17:$A$34,AA$17:AA$34,">0"),)*1.746/100)+3.5),TRUE(),"-") -> #NAME? | AC7: =_xludf.IFS(AC17="","",AC15="Teste de Esteira Progressiva",(0.2*(AC11*16.66))+((0.9*(AC11*16.66))*(OFFSET($B$17,_xludf.MAXIFS($A$17:$A$34,AC$17:AC$34,">0"),)*1.746/100)+3.5),TRUE(),"-") -> #NAME? | AE7: =_xludf.IFS(AE17="","",AE15="Teste de Esteira Progressiva",(0.2*(AE11*16.66))+((0.9*(AE11*16.66))*(OFFSET($B$17,_xludf.MAXIFS($A$17:$A$34,AE$17:AE$34,">0"),)*1.746/100)+3.5),TRUE(),"-") -> #NAME? | AG7: =_xludf.IFS(AG17="","",AG15="Teste de Esteira Progressiva",(0.2*(AG11*16.66))+((0.9*(AG11*16.66))*(OFFSET($B$17,_xludf.MAXIFS($A$17:$A$34,AG$17:AG$34,">0"),)*1.746/100)+3.5),TRUE(),"-") -> #NAME?
A8: Limiar anaeróbico(bpm) | E8: =IF(E17="","",E65) -> 138.5 | F8: 143 | G8: =IF(G17="","",G65) -> 148.4 | H8: 148 | I8: =IF(I17="","",I65) -> 143.3 | K8: =IF(K17="","",K65) -> 147.3 | L8: 155 | M8: =IF(M17="","",M65) -> 145.8 | N8: 147 | O8: =IF(O17="","",O65) -> 135.55 | Q8: =IF(Q17="","",Q65) -> 136.85 | R8: 138 | S8: =IF(S17="","",S65) | U8: =IF(U17="","",U65) | W8: =IF(W17="","",W65) | Y8: =IF(Y17="","",Y65) | AA8: =IF(AA17="","",AA65) | AC8: =IF(AC17="","",AC65) | AE8: =IF(AE17="","",AE65) | AG8: =IF(AG17="","",AG65)
A9: Limiar anaeróbico (km/h ou watts) | E9: =IF(E17="","",F65) -> #NAME? | G9: =IF(G17="","",H65) -> #NAME? | H9: 14 | I9: =IF(I17="","",J65) -> #NAME? | K9: =IF(K17="","",L65) -> #NAME? | L9: 16 | M9: =IF(M17="","",N65) -> #NAME? | N9: 15 | O9: =IF(O17="","",P65) -> #NAME? | Q9: =IF(Q17="","",R65) -> #NAME? | R9: 15 | S9: =IF(S17="","",T65) | U9: =IF(U17="","",V65) | W9: =IF(W17="","",X65) | Y9: =IF(Y17="","",Z65) | AA9: =IF(AA17="","",AB65) | AC9: =IF(AC17="","",AD65) | AE9: =IF(AE17="","",AF65) | AG9: =IF(AG17="","",AH65)
A10: Limiar anaeróbico (pace) | E10: =IF(E17="","",IF(AND(E15="Teste de esteira progressiva",E9>0),60/E9,"")) -> #NAME? | F10: =IF(AND(E15="Teste de Esteira Progressiva",F9>0),60/F9,"") | G10: =IF(G17="","",IF(AND(G15="Teste de esteira progressiva",G9>0),60/G9,"")) -> #NAME? | H10: =IF(AND(G15="Teste de Esteira Progressiva",H9>0),60/H9,"") -> 4.2857143 | I10: =IF(I17="","",IF(AND(I15="Teste de esteira progressiva",I9>0),60/I9,"")) -> #NAME? | J10: =IF(AND(I15="Teste de Esteira Progressiva",J9>0),60/J9,"") | K10: =IF(K17="","",IF(AND(K15="Teste de esteira progressiva",K9>0),60/K9,"")) -> #NAME? | L10: =IF(AND(K15="Teste de Esteira Progressiva",L9>0),60/L9,"") -> 3.75 | M10: =IF(M17="","",IF(AND(M15="Teste de esteira progressiva",M9>0),60/M9,"")) -> #NAME? | N10: =IF(AND(M15="Teste de Esteira Progressiva",N9>0),60/N9,"") -> 4 | O10: =IF(O17="","",IF(AND(O15="Teste de esteira progressiva",O9>0),60/O9,"")) -> #NAME? | P10: =IF(AND(O15="Teste de Esteira Progressiva",P9>0),60/P9,"") | Q10: =IF(Q17="","",IF(AND(Q15="Teste de esteira progressiva",Q9>0),60/Q9,"")) -> #NAME? | R10: =IF(AND(Q15="Teste de Esteira Progressiva",R9>0),60/R9,"") -> 4 | S10: =IF(S17="","",IF(AND(S15="Teste de esteira progressiva",S9>0),60/S9,"")) | T10: =IF(AND(S15="Teste de Esteira Progressiva",T9>0),60/T9,"") | U10: =IF(U17="","",IF(AND(U15="Teste de esteira progressiva",U9>0),60/U9,"")) | V10: =IF(AND(U15="Teste de Esteira Progressiva",V9>0),60/V9,"") | W10: =IF(W17="","",IF(AND(W15="Teste de esteira progressiva",W9>0),60/W9,"")) | X10: =IF(AND(W15="Teste de Esteira Progressiva",X9>0),60/X9,"") | Y10: =IF(Y17="","",IF(AND(Y15="Teste de esteira progressiva",Y9>0),60/Y9,"")) | Z10: =IF(AND(Y15="Teste de Esteira Progressiva",Z9>0),60/Z9,"") | AA10: =IF(AA17="","",IF(AND(AA15="Teste de esteira progressiva",AA9>0),60/AA9,"")) | AB10: =IF(AND(AA15="Teste de Esteira Progressiva",AB9>0),60/AB9,"") | AC10: =IF(AC17="","",IF(AND(AC15="Teste de esteira progressiva",AC9>0),60/AC9,"")) | AD10: =IF(AND(AC15="Teste de Esteira Progressiva",AD9>0),60/AD9,"") | AE10: =IF(AE17="","",IF(AND(AE15="Teste de esteira progressiva",AE9>0),60/AE9,"")) | AF10: =IF(AND(AE15="Teste de Esteira Progressiva",AF9>0),60/AF9,"") | AG10: =IF(AG17="","",IF(AND(AG15="Teste de esteira progressiva",AG9>0),60/AG9,"")) | AH10: =IF(AND(AG15="Teste de Esteira Progressiva",AH9>0),60/AH9,"")
A11: Velocidade Máxima (km/h ou watts) | E11: =IF(E17="","",OFFSET($B$17,_xludf.MAXIFS($A$17:$A$34,E$17:E$34,">0")-(E38="Estágio Interrompido"),_xludf.IFS(E$15="Teste de Esteira Progressiva",1,E$15="Teste Bicicleta ergométrica Balke",2))) -> #NAME? | G11: =IF(G17="","",OFFSET($B$17,_xludf.MAXIFS($A$17:$A$34,G$17:G$34,">0")-(G38="Estágio Interrompido"),_xludf.IFS(G$15="Teste de Esteira Progressiva",1,G$15="Teste Bicicleta ergométrica Balke",2))) -> #NAME? | I11: =IF(I17="","",OFFSET($B$17,_xludf.MAXIFS($A$17:$A$34,I$17:I$34,">0")-(I38="Estágio Interrompido"),_xludf.IFS(I$15="Teste de Esteira Progressiva",1,I$15="Teste Bicicleta ergométrica Balke",2))) -> #NAME? | K11: =IF(K17="","",OFFSET($B$17,_xludf.MAXIFS($A$17:$A$34,K$17:K$34,">0")-(K38="Estágio Interrompido"),_xludf.IFS(K$15="Teste de Esteira Progressiva",1,K$15="Teste Bicicleta ergométrica Balke",2))) -> #NAME? | L11: 18 | M11: =IF(M17="","",OFFSET($B$17,_xludf.MAXIFS($A$17:$A$34,M$17:M$34,">0")-(M38="Estágio Interrompido"),_xludf.IFS(M$15="Teste de Esteira Progressiva",1,M$15="Teste Bicicleta ergométrica Balke",2))) -> #NAME? | N11: 18 | O11: =IF(O17="","",OFFSET($B$17,_xludf.MAXIFS($A$17:$A$34,O$17:O$34,">0")-(O38="Estágio Interrompido"),_xludf.IFS(O$15="Teste de Esteira Progressiva",1,O$15="Teste Bicicleta ergométrica Balke",2))) -> #NAME? | Q11: =IF(Q17="","",OFFSET($B$17,_xludf.MAXIFS($A$17:$A$34,Q$17:Q$34,">0")-(Q38="Estágio Interrompido"),_xludf.IFS(Q$15="Teste de Esteira Progressiva",1,Q$15="Teste Bicicleta ergométrica Balke",2))) -> #NAME? | R11: 19 | S11: =IF(S17="","",OFFSET($B$17,_xludf.MAXIFS($A$17:$A$34,S$17:S$34,">0")-(S38="Estágio Interrompido"),_xludf.IFS(S$15="Teste de Esteira Progressiva",1,S$15="Teste Bicicleta ergométrica Balke",2))) | U11: =IF(U17="","",OFFSET($B$17,_xludf.MAXIFS($A$17:$A$34,U$17:U$34,">0")-(U38="Estágio Interrompido"),_xludf.IFS(U$15="Teste de Esteira Progressiva",1,U$15="Teste Bicicleta ergométrica Balke",2))) | W11: =IF(W17="","",OFFSET($B$17,_xludf.MAXIFS($A$17:$A$34,W$17:W$34,">0")-(W38="Estágio Interrompido"),_xludf.IFS(W$15="Teste de Esteira Progressiva",1,W$15="Teste Bicicleta ergométrica Balke",2))) | Y11: =IF(Y17="","",OFFSET($B$17,_xludf.MAXIFS($A$17:$A$34,Y$17:Y$34,">0")-(Y38="Estágio Interrompido"),_xludf.IFS(Y$15="Teste de Esteira Progressiva",1,Y$15="Teste Bicicleta ergométrica Balke",2))) | AA11: =IF(AA17="","",OFFSET($B$17,_xludf.MAXIFS($A$17:$A$34,AA$17:AA$34,">0")-(AA38="Estágio Interrompido"),_xludf.IFS(AA$15="Teste de Esteira Progressiva",1,AA$15="Teste Bicicleta ergométrica Balke",2))) | AC11: =IF(AC17="","",OFFSET($B$17,_xludf.MAXIFS($A$17:$A$34,AC$17:AC$34,">0")-(AC38="Estágio Interrompido"),_xludf.IFS(AC$15="Teste de Esteira Progressiva",1,AC$15="Teste Bicicleta ergométrica Balke",2))) | AE11: =IF(AE17="","",OFFSET($B$17,_xludf.MAXIFS($A$17:$A$34,AE$17:AE$34,">0")-(AE38="Estágio Interrompido"),_xludf.IFS(AE$15="Teste de Esteira Progressiva",1,AE$15="Teste Bicicleta ergométrica Balke",2))) | AG11: =IF(AG17="","",OFFSET($B$17,_xludf.MAXIFS($A$17:$A$34,AG$17:AG$34,">0")-(AG38="Estágio Interrompido"),_xludf.IFS(AG$15="Teste de Esteira Progressiva",1,AG$15="Teste Bicicleta ergométrica Balke",2)))
A12: FC Repouso | E12: =E17 -> 45 | G12: =G17 -> 60 | I12: =I17 -> 60 | K12: =K17 -> 64 | L12: 64 | M12: =M17 -> 54 | N12: 54 | O12: =O17 -> 48 | Q12: =Q17 -> 51 | R12: 48 | S12: =S17 -> 0 | U12: =U17 -> 0 | W12: =W17 -> 0 | Y12: =Y17 -> 0 | AA12: =AA17 -> 0 | AC12: =AC17 -> 0 | AE12: =AE17 -> 0 | AG12: =AG17 -> 0
A13: FC máxima predita (bpm) | E13: =IF(E$1="","",OFFSET(Avaliação!$C$147,,MATCH(E$1,Avaliação!$D$2:$AF$2,0))) -> 171.55 | G13: =IF(G$1="","",OFFSET(Avaliação!$C$147,,MATCH(G$1,Avaliação!$D$2:$AF$2,0))) -> 170.865 | I13: =IF(I$1="","",OFFSET(Avaliação!$C$147,,MATCH(I$1,Avaliação!$D$2:$AF$2,0))) -> 170.865 | K13: =IF(K$1="","",OFFSET(Avaliação!$C$147,,MATCH(K$1,Avaliação!$D$2:$AF$2,0))) -> 170.18 | L13: 170 | M13: =IF(M$1="","",OFFSET(Avaliação!$C$147,,MATCH(M$1,Avaliação!$D$2:$AF$2,0))) -> 170.18 | N13: 170 | O13: =IF(O$1="","",OFFSET(Avaliação!$C$147,,MATCH(O$1,Avaliação!$D$2:$AF$2,0))) -> 169.495 | Q13: =IF(Q$1="","",OFFSET(Avaliação!$C$147,,MATCH(Q$1,Avaliação!$D$2:$AF$2,0))) -> 169.495 | R13: 170 | S13: =IF(S$1="","",OFFSET(Avaliação!$C$147,,MATCH(S$1,Avaliação!$D$2:$AF$2,0))) | U13: =IF(U$1="","",OFFSET(Avaliação!$C$147,,MATCH(U$1,Avaliação!$D$2:$AF$2,0))) | W13: =IF(W$1="","",OFFSET(Avaliação!$C$147,,MATCH(W$1,Avaliação!$D$2:$AF$2,0))) | Y13: =IF(Y$1="","",OFFSET(Avaliação!$C$147,,MATCH(Y$1,Avaliação!$D$2:$AF$2,0))) | AA13: =IF(AA$1="","",OFFSET(Avaliação!$C$147,,MATCH(AA$1,Avaliação!$D$2:$AF$2,0))) | AC13: =IF(AC$1="","",OFFSET(Avaliação!$C$147,,MATCH(AC$1,Avaliação!$D$2:$AF$2,0))) | AE13: =IF(AE$1="","",OFFSET(Avaliação!$C$147,,MATCH(AE$1,Avaliação!$D$2:$AF$2,0))) | AG13: =IF(AG$1="","",OFFSET(Avaliação!$C$147,,MATCH(AG$1,Avaliação!$D$2:$AF$2,0)))
