Workbook

Sheet Tela Inicial - Calendário
E2: ='Dados de Base'!G2 -> Claudinei Gasparoto
E3: ='Dados de Base'!G3 -> Planilha 37
C5: Semana | D5: Dias | E5: Acesso
C6: 1 | D6: ="De "&TEXT(G6,"dd/mm")&" a "&TEXT(G6+6,"dd/mm") -> De 12/01 a 18/01 | G6: =Montagem!$C$12 -> 46034
C7: 2 | D7: ="De "&TEXT(G7,"dd/mm")&" a "&TEXT(G7+6,"dd/mm") -> De 19/01 a 25/01 | G7: =Montagem!$C$62 -> 46041
C8: 3 | D8: ="De "&TEXT(G8,"dd/mm")&" a "&TEXT(G8+6,"dd/mm") -> De 26/01 a 01/02 | G8: =Montagem!$C$112 -> 46048
C9: 4 | D9: ="De "&TEXT(G9,"dd/mm")&" a "&TEXT(G9+6,"dd/mm") -> De 02/02 a 08/02 | G9: =Montagem!$C$162 -> 46055
C10: 5 | D10: ="De "&TEXT(G10,"dd/mm")&" a "&TEXT(G10+6,"dd/mm") -> De 09/02 a 15/02 | G10: =Montagem!$C$212 -> 46062
C11: Área do professor | E11: Versão 2.6.03

Sheet Semana 1
A1: ='Periodização Macrociclo'!$N$1 -> Claudinei Gasparoto | R1: =$A1 -> Claudinei Gasparoto | AI1: =$A1 -> Claudinei Gasparoto | AZ1: =$A1 -> Claudinei Gasparoto | BQ1: =$A1 -> Claudinei Gasparoto | CH1: =$A1 -> Claudinei Gasparoto | CY1: =$A1 -> Claudinei Gasparoto
A2: Meso | B2: =Montagem!C2 -> 8 | C2: Micro | D2: =Montagem!F2 -> 29 | E2: Sessões na semana | J2: =Montagem!B43 -> 6 | K2: =IF(L2=0,0,L2-2&" a "&L2) -> 0 a 2 | L2: =Montagem!O5 -> 2 | R2: Meso | S2: =B2 -> 8 | T2: Micro | U2: =D2 -> 29 | V2: Sessões na semana | AA2: =J2 -> 6 | AI2: Meso | AJ2: =B2 -> 8 | AK2: Micro | AL2: =D2 -> 29 | AM2: Sessões na semana | AR2: =J2 -> 6 | AZ2: Meso | BA2: =B2 -> 8 | BB2: Micro | BC2: =D2 -> 29 | BD2: Sessões na semana | BI2: =J2 -> 6 | BQ2: Meso | BR2: =B2 -> 8 | BS2: Micro | BT2: =D2 -> 29 | BU2: Sessões na semana | BZ2: =J2 -> 6 | CH2: Meso | CI2: =B2 -> 8 | CJ2: Micro | CK2: =D2 -> 29 | CL2: Sessões na semana | CQ2: =J2 -> 6 | CY2: Meso | CZ2: =B2 -> 8 | DA2: Micro | DB2: =D2 -> 29 | DC2: Sessões na semana | DH2: =J2 -> 6 | DP2: Volume Total de Treinamento (min) | DQ2: =IF(L80>0,G9,0)+IF(AC80>0,X9,0)+IF(AT80>0,AO9,0)+IF(BK80>0,BF9,0)+IF(CB80>0,BW9,0)+IF(CS80>0,CN9,0)+IF(DJ80>0,DE9,0) -> 0
A3: =Montagem!K8 -> 46034 | B3: =Montagem!K9 -> Segunda-Feira | K3: =DQ17-DQ18 -> 6 | R3: =Montagem!Z8 -> 46035 | S3: =Montagem!Z9 -> Terça-Feira | AI3: =Montagem!AO8 -> 46036 | AJ3: =Montagem!AO9 -> Quarta-Feira | AZ3: =Montagem!BD8 -> 46037 | BA3: =Montagem!BD9 -> Quinta Feira | BQ3: =Montagem!BS8 -> 46038 | BR3: =Montagem!BS9 -> Sexta-Feira | CH3: =Montagem!CH8 -> 46039 | CI3: =Montagem!CH9 -> Sábado | CY3: =Montagem!CW8 -> 46040 | CZ3: =Montagem!CW9 -> Domingo | DP3: Volume de Treinamento Cíclico (min) | DQ3: =IF(L80>0,IF(ISNUMBER(B82),B82,B6),0)+IF(AC80>0,IF(ISNUMBER(S82),S82,S6),0)+IF(AT80>0,IF(ISNUMBER(AJ82),AJ82,AJ6),0)+IF(BK80>0,IF(ISNUMBER(BA82),BA82,BA6),0)+IF(CB80>0,IF(ISNUMBER(BR82),BR82,BR6),0)+IF(CS80>0,IF(ISNUMBER(CI82),CI82,CI6),0)+IF(DJ80>0,IF(ISNUMBER(CZ82),CZ82,CZ6),0) -> 0
A4: Quao recuperado você esta se sentindo (PSR)? | D4: 10 - Totalmente Recuperado | K4: =IF(D4="","",LEFT(D4,2)+0) -> 10 | R4: Quao recuperado você esta se sentindo (PSR)? | AB4: =IF(U4="","",LEFT(U4,2)+0) | AI4: Quao recuperado você esta se sentindo (PSR)? | AS4: =IF(AL4="","",LEFT(AL4,2)+0) | AZ4: Quao recuperado você esta se sentindo (PSR)? | BJ4: =IF(BC4="","",LEFT(BC4,2)+0) | BQ4: Quao recuperado você esta se sentindo (PSR)? | CA4: =IF(BT4="","",LEFT(BT4,2)+0) | CH4: Quao recuperado você esta se sentindo (PSR)? | CR4: =IF(CK4="","",LEFT(CK4,2)+0) | CY4: Quao recuperado você esta se sentindo (PSR)? | DI4: =IF(DB4="","",LEFT(DB4,2)+0) | DP4: Volume de Treinamento Cíclico (km) | DQ4: =IF(L80>0,D82,0)+IF(AC80>0,U82,0)+IF(AT80>0,AL82,0)+IF(BK80>0,BC82,0)+IF(CB80>0,BT82,0)+IF(CS80>0,CK82,0)+IF(DJ80>0,DB82,0) -> 0
A5: =IF(G9=10,"Tenha um bom descanso!😉💤","TREINAMENTO CÍCLICO") -> TREINAMENTO CÍCLICO | R5: =IF(X9=10,"Tenha um bom descanso!😉💤","TREINAMENTO CÍCLICO") -> TREINAMENTO CÍCLICO | AI5: =IF(AO9=10,"Tenha um bom descanso!😉💤","TREINAMENTO CÍCLICO") -> TREINAMENTO CÍCLICO | AZ5: =IF(BF9=10,"Tenha um bom descanso!😉💤","TREINAMENTO CÍCLICO") -> TREINAMENTO CÍCLICO | BQ5: =IF(BW9=10,"Tenha um bom descanso!😉💤","TREINAMENTO CÍCLICO") -> TREINAMENTO CÍCLICO | CH5: =IF(CN9=10,"Tenha um bom descanso!😉💤","TREINAMENTO CÍCLICO") -> TREINAMENTO CÍCLICO | CY5: =IF(DE9=10,"Tenha um bom descanso!😉💤","TREINAMENTO CÍCLICO") -> Tenha um bom descanso!😉💤 | DP5: Volume de Treinamento Resistido (séries) | DQ5: =IF(L80>0,B8,0)+IF(AC80>0,S8,0)+IF(AT80>0,AJ8,0)+IF(BK80>0,BA8,0)+IF(CB80>0,BR8,0)+IF(CS80>0,CI8,0)+IF(DJ80>0,CZ8,0) -> 0
A6: Volume | B6: =Montagem!C15 -> 25 | C6: Método | D6: =Montagem!C17 -> CEXT | F6: KCAL est. | H6: =0.0175*IF(ISNUMBER(B82),B82,B6)*'Dados de Base'!$D$5*('Dados de Base'!$D$7*IF(ISNUMBER(G82),(G82-'Dados de Base'!$F$6)/('Dados de Base'!$E$20-'Dados de Base'!$F$6),Montagem!C27)) -> 248.61375 | R6: Volume | S6: =Montagem!D15 -> 5 | T6: Método | U6: =Montagem!D17 -> IINT | W6: KCAL est. | Y6: =0.0175*IF(ISNUMBER(S82),S82,S6)*'Dados de Base'!$D$5*('Dados de Base'!$D$7*IF(ISNUMBER(X82),(X82-'Dados de Base'!$F$6)/('Dados de Base'!$E$20-'Dados de Base'!$F$6),Montagem!D27)) -> 0 | AI6: Volume | AJ6: =Montagem!E15 | AK6: Método | AL6: =Montagem!E17 | AN6: KCAL est. | AP6: =0.0175*IF(ISNUMBER(AJ82),AJ82,AJ6)*'Dados de Base'!$D$5*('Dados de Base'!$D$7*IF(ISNUMBER(AO82),(AO82-'Dados de Base'!$F$6)/('Dados de Base'!$E$20-'Dados de Base'!$F$6),Montagem!E27)) -> 0 | AZ6: Volume | BA6: =Montagem!F15 -> 6 | BB6: Método | BC6: =Montagem!F17 -> IINT | BE6: KCAL est. | BG6: =0.0175*IF(ISNUMBER(BA82),BA82,BA6)*'Dados de Base'!$D$5*('Dados de Base'!$D$7*IF(ISNUMBER(BF82),(BF82-'Dados de Base'!$F$6)/('Dados de Base'!$E$20-'Dados de Base'!$F$6),Montagem!F27)) -> 0 | BQ6: Volume | BR6: =Montagem!G15 -> 35 | BS6: Método | BT6: =Montagem!G17 -> CEXT | BV6: KCAL est. | BX6: =0.0175*IF(ISNUMBER(BR82),BR82,BR6)*'Dados de Base'!$D$5*('Dados de Base'!$D$7*IF(ISNUMBER(BW82),(BW82-'Dados de Base'!$F$6)/('Dados de Base'!$E$20-'Dados de Base'!$F$6),Montagem!G27)) -> 348.05925 | CH6: Volume | CI6: =Montagem!H15 | CJ6: Método | CK6: =Montagem!H17 | CM6: KCAL est. | CO6: =0.0175*IF(ISNUMBER(CI82),CI82,CI6)*'Dados de Base'!$D$5*('Dados de Base'!$D$7*IF(ISNUMBER(CN82),(CN82-'Dados de Base'!$F$6)/('Dados de Base'!$E$20-'Dados de Base'!$F$6),Montagem!H27)) -> 0 | CY6: Volume | CZ6: =Montagem!I15 | DA6: Método | DB6: =Montagem!I17 | DD6: KCAL est. | DF6: =0.0175*IF(ISNUMBER(CZ82),CZ82,CZ6)*'Dados de Base'!$D$5*('Dados de Base'!$D$7*IF(ISNUMBER(DE82),(DE82-'Dados de Base'!$F$6)/('Dados de Base'!$E$20-'Dados de Base'!$F$6),Montagem!I27)) -> 0 | DP6: Numero de Repetições | DQ6: =IF(L80>0,E8,0)+IF(AC80>0,V8,0)+IF(AT80>0,AM8,0)+IF(BK80>0,BD8,0)+IF(CB80>0,BU8,0)+IF(CS80>0,CL8,0)+IF(DJ80>0,DC8,0) -> 0
A7: =IF(G9=10,"Se você tem treino programado nesta data, entre em contato com a equipe para atualizarmos a sessão!","TREINAMENTO RESISTIDO") -> TREINAMENTO RESISTIDO | R7: =IF(X9=10,"Se você tem treino programado nesta data, entre em contato com a equipe para atualizarmos a sessão!","TREINAMENTO RESISTIDO") -> TREINAMENTO RESISTIDO | AI7: =IF(AO9=10,"Se você tem treino programado nesta data, entre em contato com a equipe para atualizarmos a sessão!","TREINAMENTO RESISTIDO") -> TREINAMENTO RESISTIDO | AZ7: =IF(BF9=10,"Se você tem treino programado nesta data, entre em contato com a equipe para atualizarmos a sessão!","TREINAMENTO RESISTIDO") -> TREINAMENTO RESISTIDO | BQ7: =IF(BW9=10,"Se você tem treino programado nesta data, entre em contato com a equipe para atualizarmos a sessão!","TREINAMENTO RESISTIDO") -> TREINAMENTO RESISTIDO | CH7: =IF(CN9=10,"Se você tem treino programado nesta data, entre em contato com a equipe para atualizarmos a sessão!","TREINAMENTO RESISTIDO") -> TREINAMENTO RESISTIDO | CY7: =IF(DE9=10,"Se você tem treino programado nesta data, entre em contato com a equipe para atualizarmos a sessão!","TREINAMENTO RESISTIDO") -> Se você tem treino programado nesta data, entre em contato com a equipe para atualizarmos a sessão! | DP7: Volume de Treinamento Resistido (t) | DQ7: =E83+V83+AM83+BD83+BU83+CL83+DC83 -> 0
A8: N. Séries | B8: =SUM(E16,E18,E20,E22,E26,E28,E30,E32,E34,E36,E38,E40,E42,E44,E46,E48,E50,E52,E54,E56,E58,E60,E62,E64,E68,E70,E72) -> 46 | C8: N. repetições | E8: =SUM(E16*F16,E18*F18,E20*F20,E22*F22,E26*F26,E28*F28,E30*F30,E32*F32,E34*F34,E36*F36,E38*F38,E40*F40,E42*F42,E44*F44,E46*F46,E48*F48,E50*F50,E52*F52,E54*F54,E56*F56,E58*F58,E60*F60,E62*F62,E64*F64,E68*F68,E70*F70,E72*F72) -> 460 | F8: KCAL est. | H8: =0.0175*'Dados de Base'!$D$5*D89*5 -> 119.4375 | R8: N. Séries | S8: =SUM(V16,V18,V20,V22,V26,V28,V30,V32,V34,V36,V38,V40,V42,V44,V46,V48,V50,V52,V54,V56,V58,V60,V62,V64,V68,V70,V72) -> 42 | T8: N. repetições | V8: =SUM(V16*W16,V18*W18,V20*W20,V22*W22,V26*W26,V28*W28,V30*W30,V32*W32,V34*W34,V36*W36,V38*W38,V40*W40,V42*W42,V44*W44,V46*W46,V48*W48,V50*W50,V52*W52,V54*W54,V56*W56,V58*W58,V60*W60,V62*W62,V64*W64,V68*W68,V70*W70,V72*W72) -> 525 | W8: KCAL est. | Y8: =0.0175*'Dados de Base'!$D$5*U89*5 -> 114.38438 | AI8: N. Séries | AJ8: =SUM(AM16,AM18,AM20,AM22,AM26,AM28,AM30,AM32,AM34,AM36,AM38,AM40,AM42,AM44,AM46,AM48,AM50,AM52,AM54,AM56,AM58,AM60,AM62,AM64,AM68,AM70,AM72) -> 5 | AK8: N. repetições | AM8: =SUM(AM16*AN16,AM18*AN18,AM20*AN20,AM22*AN22,AM26*AN26,AM28*AN28,AM30*AN30,AM32*AN32,AM34*AN34,AM36*AN36,AM38*AN38,AM40*AN40,AM42*AN42,AM44*AN44,AM46*AN46,AM48*AN48,AM50*AN50,AM52*AN52,AM54*AN54,AM56*AN56,AM58*AN58,AM60*AN60,AM62*AN62,AM64*AN64,AM68*AN68,AM70*AN70,AM72*AN72) -> 90 | AN8: KCAL est. | AP8: =0.0175*'Dados de Base'!$D$5*AL89*5 -> 11.94375 | AZ8: N. Séries | BA8: =SUM(BD16,BD18,BD20,BD22,BD26,BD28,BD30,BD32,BD34,BD36,BD38,BD40,BD42,BD44,BD46,BD48,BD50,BD52,BD54,BD56,BD58,BD60,BD62,BD64,BD68,BD70,BD72) -> 40 | BB8: N. repetições | BD8: =SUM(BD16*BE16,BD18*BE18,BD20*BE20,BD22*BE22,BD26*BE26,BD28*BE28,BD30*BE30,BD32*BE32,BD34*BE34,BD36*BE36,BD38*BE38,BD40*BE40,BD42*BE42,BD44*BE44,BD46*BE46,BD48*BE48,BD50*BE50,BD52*BE52,BD54*BE54,BD56*BE56,BD58*BE58,BD60*BE60,BD62*BE62,BD64*BE64,BD68*BE68,BD70*BE70,BD72*BE72) -> 410 | BE8: KCAL est. | BG8: =0.0175*'Dados de Base'!$D$5*BC89*5 -> 107.49375 | BQ8: N. Séries | BR8: =SUM(BU16,BU18,BU20,BU22,BU26,BU28,BU30,BU32,BU34,BU36,BU38,BU40,BU42,BU44,BU46,BU48,BU50,BU52,BU54,BU56,BU58,BU60,BU62,BU64,BU68,BU70,BU72) -> 46 | BS8: N. repetições | BU8: =SUM(BU16*BV16,BU18*BV18,BU20*BV20,BU22*BV22,BU26*BV26,BU28*BV28,BU30*BV30,BU32*BV32,BU34*BV34,BU36*BV36,BU38*BV38,BU40*BV40,BU42*BV42,BU44*BV44,BU46*BV46,BU48*BV48,BU50*BV50,BU52*BV52,BU54*BV54,BU56*BV56,BU58*BV58,BU60*BV60,BU62*BV62,BU64*BV64,BU68*BV68,BU70*BV70,BU72*BV72) -> 460 | BV8: KCAL est. | BX8: =0.0175*'Dados de Base'!$D$5*BT89*5 -> 119.4375 | CH8: N. Séries | CI8: =SUM(CL16,CL18,CL20,CL22,CL26,CL28,CL30,CL32,CL34,CL36,CL38,CL40,CL42,CL44,CL46,CL48,CL50,CL52,CL54,CL56,CL58,CL60,CL62,CL64,CL68,CL70,CL72) -> 6 | CJ8: N. repetições | CL8: =SUM(CL16*CM16,CL18*CM18,CL20*CM20,CL22*CM22,CL26*CM26,CL28*CM28,CL30*CM30,CL32*CM32,CL34*CM34,CL36*CM36,CL38*CM38,CL40*CM40,CL42*CM42,CL44*CM44,CL46*CM46,CL48*CM48,CL50*CM50,CL52*CM52,CL54*CM54,CL56*CM56,CL58*CM58,CL60*CM60,CL62*CM62,CL64*CM64,CL68*CM68,CL70*CM70,CL72*CM72) -> 100 | CM8: KCAL est. | CO8: =0.0175*'Dados de Base'!$D$5*CK89*5 -> 9.1875 | CY8: N. Séries | CZ8: =SUM(DC16,DC18,DC20,DC22,DC26,DC28,DC30,DC32,DC34,DC36,DC38,DC40,DC42,DC44,DC46,DC48,DC50,DC52,DC54,DC56,DC58,DC60,DC62,DC64,DC68,DC70,DC72) -> 0 | DA8: N. repetições | DC8: =SUM(DC16*DD16,DC18*DD18,DC20*DD20,DC22*DD22,DC26*DD26,DC28*DD28,DC30*DD30,DC32*DD32,DC34*DD34,DC36*DD36,DC38*DD38,DC40*DD40,DC42*DD42,DC44*DD44,DC46*DD46,DC48*DD48,DC50*DD50,DC52*DD52,DC54*DD54,DC56*DD56,DC58*DD58,DC60*DD60,DC62*DD62,DC64*DD64,DC68*DD68,DC70*DD70,DC72*DD72) -> 0 | DD8: KCAL est. | DF8: =0.0175*'Dados de Base'!$D$5*DB89*5 -> 0 | DP8: Tempo sob Tensão (min) | DQ8: =IF(L80>0,D89,0)+IF(AC80>0,U89,0)+IF(AT80>0,AL89,0)+IF(BK80>0,BC89,0)+IF(CB80>0,BT89,0)+IF(CS80>0,CK89,0)+IF(DJ80>0,DB89,0) -> 0
A9: TEMPO ESTIMADO PARA A SESSÃO (min) | G9: =((D89+K89+IF(ISNUMBER(B82),B82,B6))*Montagem!AS3)+10 -> 73.25 | R9: TEMPO ESTIMADO PARA A SESSÃO (min) | X9: =((U89+AB89+IF(ISNUMBER(S82),S82,S6))*Montagem!AS3)+10 -> 51.25 | AI9: TEMPO ESTIMADO PARA A SESSÃO (min) | AO9: =((AL89+AS89+IF(ISNUMBER(AJ82),AJ82,AJ6))*Montagem!AS3)+10 -> 13.833333 | AZ9: TEMPO ESTIMADO PARA A SESSÃO (min) | BF9: =((BC89+BJ89+IF(ISNUMBER(BA82),BA82,BA6))*Montagem!AS3)+10 -> 51 | BQ9: TEMPO ESTIMADO PARA A SESSÃO (min) | BW9: =((BT89+CA89+IF(ISNUMBER(BR82),BR82,BR6))*Montagem!AS3)+10 -> 83.25 | CH9: TEMPO ESTIMADO PARA A SESSÃO (min) | CN9: =((CK89+CR89+IF(ISNUMBER(CI82),CI82,CI6))*Montagem!AS3)+10 -> 13.333333 | CY9: TEMPO ESTIMADO PARA A SESSÃO (min) | DE9: =((DB89+DI89+IF(ISNUMBER(CZ82),CZ82,CZ6))*Montagem!AS3)+10 -> 10 | DP9: Gasto Energético (kcal) | DQ9: =IF(L80>0,H8+H6,0)+IF(AC80>0,Y8+Y6,0)+IF(AT80>0,AP8+AP6,0)+IF(BK80>0,BG8+BG6,0)+IF(CB80>0,BX8+BX6,0)+IF(CS80>0,CO8+CO6,0)+IF(DJ80>0,DF8+DF6,0) -> 0
A10: ORIENTAÇÕES GERAIS | R10: ORIENTAÇÕES GERAIS | AI10: ORIENTAÇÕES GERAIS | AZ10: ORIENTAÇÕES GERAIS | BQ10: ORIENTAÇÕES GERAIS | CH10: ORIENTAÇÕES GERAIS | CY10: ORIENTAÇÕES GERAIS | DP10: Gasto Energético Média/dia (kcal) | DQ10: =DQ9/7 -> 0
A11: =Montagem!K12 | R11: =Montagem!Z12 | AI11: =Montagem!AO12 | AZ11: =Montagem!BD12 | BQ11: =Montagem!BS12 | CH11: =Montagem!CH12 | CY11: =Montagem!CW12 | DP11: Carga Interna de Treinamento (ua) | DQ11: =SUM(D90,U90,AL90,BC90,BT90,CK90,DB90) -> 0
A12: =Montagem!K13 | R12: =Montagem!Z13 | AI12: =Montagem!AO13 | AZ12: =Montagem!BD13 | BQ12: =Montagem!BS13 | CH12: =Montagem!CH13 | CY12: =Montagem!CW13 | DP12: Carga Interna de Treinamento Média da Sessão | DQ12: =IF(DQ18=0,0,DQ11/DQ18) -> 0
A13: =IFS(L2=4,"Semana de Adaptação",L2=2,"Semana Ordinária",L2=0,"Semana de Choque") -> Semana Ordinária | R13: =IFS(L2=4,"Semana de Adaptação",L2=2,"Semana Ordinária",L2=0,"Semana de Choque") -> Semana Ordinária | AI13: =IFS(L2=4,"Semana de Adaptação",L2=2,"Semana Ordinária",L2=0,"Semana de Choque") -> Semana Ordinária | AZ13: =IFS(L2=4,"Semana de Adaptação",L2=2,"Semana Ordinária",L2=0,"Semana de Choque") -> Semana Ordinária | BQ13: =IFS(L2=4,"Semana de Adaptação",L2=2,"Semana Ordinária",L2=0,"Semana de Choque") -> Semana Ordinária | CH13: =IFS(L2=4,"Semana de Adaptação",L2=2,"Semana Ordinária",L2=0,"Semana de Choque") -> Semana Ordinária | CY13: =IFS(L2=4,"Semana de Adaptação",L2=2,"Semana Ordinária",L2=0,"Semana de Choque") -> Semana Ordinária | DP13: Carga Interna de Treinamento Média Diária | DQ13: =DQ11/7 -> 0
A14: MOBILIDADE | AQUECIMENTO | ATIVAÇÃO | TÉCNICO | R14: MOBILIDADE | AQUECIMENTO | ATIVAÇÃO | TÉCNICO | AI14: MOBILIDADE | AQUECIMENTO | ATIVAÇÃO | TÉCNICO | AZ14: MOBILIDADE | AQUECIMENTO | ATIVAÇÃO | TÉCNICO | BQ14: MOBILIDADE | AQUECIMENTO | ATIVAÇÃO | TÉCNICO | CH14: MOBILIDADE | AQUECIMENTO | ATIVAÇÃO | TÉCNICO | CY14: MOBILIDADE | AQUECIMENTO | ATIVAÇÃO | TÉCNICO | DP14: Carga Interna de Treinamento - Desvio Padrão | DQ14: =STDEVPA(D90,U90,AL90,BC90,BT90,CK90,DB90) -> 0
A15: Exercício | D15: Sistema | E15: Séries | F15: Reps | G15: Int | H15: C | I15: E | J15: Carga | R15: Exercício | U15: Sistema | V15: Séries | W15: Reps | X15: Int | Y15: C | Z15: E | AA15: Carga | AI15: Exercício | AL15: Sistema | AM15: Séries | AN15: Reps | AO15: Int | AP15: C | AQ15: E | AR15: Carga | AZ15: Exercício | BC15: Sistema | BD15: Séries | BE15: Reps | BF15: Int | BG15: C | BH15: E | BI15: Carga | BQ15: Exercício | BT15: Sistema | BU15: Séries | BV15: Reps | BW15: Int | BX15: C | BY15: E | BZ15: Carga | CH15: Exercício | CK15: Sistema | CL15: Séries | CM15: Reps | CN15: Int | CO15: C | CP15: E | CQ15: Carga | CY15: Exercício | DB15: Sistema | DC15: Séries | DD15: Reps | DE15: Int | DF15: C | DG15: E | DH15: Carga | DP15: PSR Média | DQ15: =IF(ISERR(AVERAGE(K4,AB4,AS4,BJ4,CA4,CR4,DI4)),0,AVERAGE(K4,AB4,AS4,BJ4,CA4,CR4,DI4)) -> 10
A16: =IF(M16="","",HYPERLINK(OFFSET(Biblioteca!$B$2,MATCH(M16,Biblioteca!$A$3:$A$200,0),0),M16)) -> Mobilidade de Quadril - Iliopsoas | D16: =Montagem!Q16 -> Seriado | E16: =Montagem!R16 -> 2 | F16: =Montagem!S16 -> 10 | G16: =Montagem!T16 -> 10 | H16: =Montagem!U16 -> 1 | I16: =Montagem!V16 -> 1 | J16: 10 | K16: =Montagem!K16 -> 1 | L16: =Montagem!W16 -> 0 | M16: =Montagem!L16 -> Mobilidade de Quadril - Iliopsoas | N16: =Montagem!X16 | O16: =IF(N16="",L16,N16) -> 0 | P16: =IF(L17="C",'Dados de Base'!$D$5*0.1,IF(L17="E",5,IF(J16="",O16,J16))) -> 6.3 | R16: =IF(AD16="","",HYPERLINK(OFFSET(Biblioteca!$B$2,MATCH(AD16,Biblioteca!$A$3:$A$200,0),0),AD16)) -> Mobilidade de Quadril em S | U16: =Montagem!AF16 -> Seriado | V16: =Montagem!AG16 -> 2 | W16: =Montagem!AH16 -> 10 | X16: =Montagem!AI16 -> 10 | Y16: =Montagem!AJ16 -> 1 | Z16: =Montagem!AK16 -> 1 | AB16: =Montagem!Z16 -> 1 | AC16: =Montagem!AL16 -> 0 | AD16: =Montagem!AA16 -> Mobilidade de Quadril em S | AE16: =Montagem!AM16 | AF16: =IF(AE16="",AC16,AE16) -> 0 | AG16: =IF(AC17="C",'Dados de Base'!$D$5*0.1,IF(AC17="E",5,IF(AA16="",AF16,AA16))) -> 6.3 | AI16: =IF(AU16="","",HYPERLINK(OFFSET(Biblioteca!$B$2,MATCH(AU16,Biblioteca!$A$3:$A$200,0),0),AU16)) -> Mobilidade de Quadril - Cócoras | AL16: =Montagem!AU16 -> Seriado | AM16: =Montagem!AV16 -> 2 | AN16: =Montagem!AW16 -> 10 | AO16: =Montagem!AX16 -> 10 | AP16: =Montagem!AY16 -> 1 | AQ16: =Montagem!AZ16 -> 1 | AS16: =Montagem!AO16 -> 1 | AT16: =Montagem!BA16 -> 0 | AU16: =Montagem!AP16 -> Mobilidade de Quadril - Cócoras | AV16: =Montagem!BB16 | AW16: =IF(AV16="",AT16,AV16) -> 0 | AX16: =IF(AT17="C",'Dados de Base'!$D$5*0.1,IF(AT17="E",5,IF(AR16="",AW16,AR16))) -> 6.3 | AZ16: =IF(BL16="","",HYPERLINK(OFFSET(Biblioteca!$B$2,MATCH(BL16,Biblioteca!$A$3:$A$200,0),0),BL16)) -> Mobilidade Torácica na Parede | BC16: =Montagem!BJ16 -> Seriado | BD16: =Montagem!BK16 -> 2 | BE16: =Montagem!BL16 -> 10 | BF16: =Montagem!BM16 -> 10 | BG16: =Montagem!BN16 -> 1 | BH16: =Montagem!BO16 -> 1 | BJ16: =Montagem!BD16 -> 1 | BK16: =Montagem!BP16 -> 0 | BL16: =Montagem!BE16 -> Mobilidade Torácica na Parede | BM16: =Montagem!BQ16 | BN16: =IF(BM16="",BK16,BM16) -> 0 | BO16: =IF(BK17="C",'Dados de Base'!$D$5*0.1,IF(BK17="E",5,IF(BI16="",BN16,BI16))) -> 6.3 | BQ16: =IF(CC16="","",HYPERLINK(OFFSET(Biblioteca!$B$2,MATCH(CC16,Biblioteca!$A$3:$A$200,0),0),CC16)) -> Mobilidade de Pelve no solo | BT16: =Montagem!BY16 -> Seriado | BU16: =Montagem!BZ16 -> 2 | BV16: =Montagem!CA16 -> 10 | BW16: =Montagem!CB16 -> 10 | BX16: =Montagem!CC16 -> 1 | BY16: =Montagem!CD16 -> 1 | CA16: =Montagem!BS16 -> 1 | CB16: =Montagem!CE16 -> 0 | CC16: =Montagem!BT16 -> Mobilidade de Pelve no solo | CD16: =Montagem!CF16 | CE16: =IF(CD16="",CB16,CD16) -> 0 | CF16: =IF(CB17="C",'Dados de Base'!$D$5*0.1,IF(CB17="E",5,IF(BZ16="",CE16,BZ16))) -> 6.3 | CH16: =IF(CT16="","",HYPERLINK(OFFSET(Biblioteca!$B$2,MATCH(CT16,Biblioteca!$A$3:$A$200,0),0),CT16)) -> Mobilidade de tornozelo | CK16: =Montagem!CN16 -> Seriado | CL16: =Montagem!CO16 -> 2 | CM16: =Montagem!CP16 -> 10 | CN16: =Montagem!CQ16 -> 10 | CO16: =Montagem!CR16 -> 0 | CP16: =Montagem!CS16 -> 1 | CR16: =Montagem!CH16 -> 1 | CS16: =Montagem!CT16 -> 0 | CT16: =Montagem!CI16 -> Mobilidade de tornozelo | CU16: =Montagem!CU16 | CV16: =IF(CU16="",CS16,CU16) -> 0 | CW16: =IF(CS17="C",'Dados de Base'!$D$5*0.1,IF(CS17="E",5,IF(CQ16="",CV16,CQ16))) -> 6.3 | CY16: =IF(DK16="","",HYPERLINK(OFFSET(Biblioteca!$B$2,MATCH(DK16,Biblioteca!$A$3:$A$200,0),0),DK16)) | DB16: =Montagem!DC16 | DC16: =Montagem!DD16 | DD16: =Montagem!DE16 | DE16: =Montagem!DF16 | DF16: =Montagem!DG16 | DG16: =Montagem!DH16 | DI16: =Montagem!CW16 -> 1 | DJ16: =Montagem!DI16 | DK16: =Montagem!CX16 | DL16: =Montagem!DJ16 | DM16: =IF(DL16="",DJ16,DL16) | DN16: =IF(DJ17="C",'Dados de Base'!$D$5*0.1,IF(DJ17="E",5,IF(DH16="",DM16,DH16))) | DP16: PSE Média | DQ16: =IF(DQ18=0,0,(L80+AC80+AT80+BK80+CB80+CS80+DJ80)/DQ18) -> 0
A17: =IF(A16="","",IFS(L17="A",Montagem!$C$30,N17="T","Realizar a maior quantidade de repetições por "&F16&" segundos | ",N17="I",IF(M17="U","Manter a posição por "&F16&" segundos de um lado e trocar para o outro na sequência | ","Manter a posição por "&F16&" segundos | "),M17="A","Realizar alternadamente "&F16&" repetições cada lado | ",M17="U","Realizar "&F16&" repetições de um lado e trocar para o outro na sequência | ",L17="P",OFFSET(Biblioteca!$H$2,MATCH(M16,Biblioteca!$A$3:$A$200,0),0),TRUE,"")) | E17: =IF(A16="","",IFS(L17="H","Carga Sugerida: "&ROUNDUP(O16/2,0)&" kg de cada lado (Total: "&ROUNDUP(O16/2,0)*2&" kg)",L17="C","Este exercício usa o Peso Corporal como carga",L17="E","Este exercício usa a resistência da banda elástica como carga",L17="O","Carga Sugerida: "&INT(O16)&" kg",TRUE,"")) -> Este exercício usa o Peso Corporal como carga | K17: =K16 -> 1 | L17: =LEFT(O17) -> C | M17: =MID(O17,2,1) -> O | N17: =RIGHT(O17) -> R | O17: =IF(M16="","",OFFSET(Biblioteca!$I$2,MATCH(M16,Biblioteca!$A$3:$A$200,0),0)) -> COR | R17: =IF(R16="","",IFS(AC17="A",Montagem!$D$30,AE17="T","Realizar a maior quantidade de repetições por "&W16&" segundos | ",AE17="I",IF(AD17="U","Manter a posição por "&W16&" segundos de um lado e trocar para o outro na sequência | ","Manter a posição por "&W16&" segundos | "),AD17="A","Realizar alternadamente "&W16&" repetições cada lado | ",AD17="U","Realizar "&W16&" repetições de um lado e trocar para o outro na sequência | ",AC17="P",OFFSET(Biblioteca!$H$2,MATCH(AD16,Biblioteca!$A$3:$A$200,0),0),TRUE,"")) -> Realizar 10 repetições de um lado e trocar para o outro na sequência | | V17: =IF(R16="","",IFS(AC17="H","Carga Sugerida: "&ROUNDUP(AF16/2,0)&" kg de cada lado (Total: "&ROUNDUP(AF16/2,0)*2&" kg)",AC17="C","Este exercício usa o Peso Corporal como carga",AC17="E","Este exercício usa a resistência da banda elástica como carga",AC17="O","Carga Sugerida: "&INT(AF16)&" kg",TRUE,"")) -> Este exercício usa o Peso Corporal como carga | AB17: =AB16 -> 1 | AC17: =LEFT(AF17) -> C | AD17: =MID(AF17,2,1) -> U | AE17: =RIGHT(AF17) -> R | AF17: =IF(AD16="","",OFFSET(Biblioteca!$I$2,MATCH(AD16,Biblioteca!$A$3:$A$200,0),0)) -> CUR | AI17: =IF(AI16="","",IFS(AT17="A",Montagem!$E$30,AV17="T","Realizar a maior quantidade de repetições por "&AN16&" segundos | ",AV17="I",IF(AU17="U","Manter a posição por "&AN16&" segundos de um lado e trocar para o outro na sequência | ","Manter a posição por "&AN16&" segundos | "),AU17="A","Realizar alternadamente "&AN16&" repetições cada lado | ",AU17="U","Realizar "&AN16&" repetições de um lado e trocar para o outro na sequência | ",AT17="P",OFFSET(Biblioteca!$H$2,MATCH(AU16,Biblioteca!$A$3:$A$200,0),0),TRUE,"")) -> Manter a posição por 10 segundos | | AM17: =IF(AI16="","",IFS(AT17="H","Carga Sugerida: "&ROUNDUP(AW16/2,0)&" kg de cada lado (Total: "&ROUNDUP(AW16/2,0)*2&" kg)",AT17="C","Este exercício usa o Peso Corporal como carga",AT17="E","Este exercício usa a resistência da banda elástica como carga",AT17="O","Carga Sugerida: "&INT(AW16)&" kg",TRUE,"")) -> Este exercício usa o Peso Corporal como carga | AS17: =AS16 -> 1 | AT17: =LEFT(AW17) -> C | AU17: =MID(AW17,2,1) -> O | AV17: =RIGHT(AW17) -> I | AW17: =IF(AU16="","",OFFSET(Biblioteca!$I$2,MATCH(AU16,Biblioteca!$A$3:$A$200,0),0)) -> COI | AZ17: =IF(AZ16="","",IFS(BK17="A",Montagem!$F$30,BM17="T","Realizar a maior quantidade de repetições por "&BE16&" segundos | ",BM17="I",IF(BL17="U","Manter a posição por "&BE16&" segundos de um lado e trocar para o outro na sequência | ","Manter a posição por "&BE16&" segundos | "),BL17="A","Realizar alternadamente "&BE16&" repetições cada lado | ",BL17="U","Realizar "&BE16&" repetições de um lado e trocar para o outro na sequência | ",BK17="P",OFFSET(Biblioteca!$H$2,MATCH(BL16,Biblioteca!$A$3:$A$200,0),0),TRUE,"")) -> Realizar 10 repetições de um lado e trocar para o outro na sequência | | BD17: =IF(AZ16="","",IFS(BK17="H","Carga Sugerida: "&ROUNDUP(BN16/2,0)&" kg de cada lado (Total: "&ROUNDUP(BN16/2,0)*2&" kg)",BK17="C","Este exercício usa o Peso Corporal como carga",BK17="E","Este exercício usa a resistência da banda elástica como carga",BK17="O","Carga Sugerida: "&INT(BN16)&" kg",TRUE,"")) -> Este exercício usa o Peso Corporal como carga | BJ17: =BJ16 -> 1 | BK17: =LEFT(BN17) -> C | BL17: =MID(BN17,2,1) -> U | BM17: =RIGHT(BN17) -> R | BN17: =IF(BL16="","",OFFSET(Biblioteca!$I$2,MATCH(BL16,Biblioteca!$A$3:$A$200,0),0)) -> CUR | BQ17: =IF(BQ16="","",IFS(CB17="A",Montagem!$G$30,CD17="T","Realizar a maior quantidade de repetições por "&BV16&" segundos | ",CD17="I",IF(CC17="U","Manter a posição por "&BV16&" segundos de um lado e trocar para o outro na sequência | ","Manter a posição por "&BV16&" segundos | "),CC17="A","Realizar alternadamente "&BV16&" repetições cada lado | ",CC17="U","Realizar "&BV16&" repetições de um lado e trocar para o outro na sequência | ",CB17="P",OFFSET(Biblioteca!$H$2,MATCH(CC16,Biblioteca!$A$3:$A$200,0),0),TRUE,"")) | BU17: =IF(BQ16="","",IFS(CB17="H","Carga Sugerida: "&ROUNDUP(CE16/2,0)&" kg de cada lado (Total: "&ROUNDUP(CE16/2,0)*2&" kg)",CB17="C","Este exercício usa o Peso Corporal como carga",CB17="E","Este exercício usa a resistência da banda elástica como carga",CB17="O","Carga Sugerida: "&INT(CE16)&" kg",TRUE,"")) -> Este exercício usa o Peso Corporal como carga | CA17: =CA16 -> 1 | CB17: =LEFT(CE17) -> C | CC17: =MID(CE17,2,1) -> O | CD17: =RIGHT(CE17) -> R | CE17: =IF(CC16="","",OFFSET(Biblioteca!$I$2,MATCH(CC16,Biblioteca!$A$3:$A$200,0),0)) -> COR | CH17: =IF(CH16="","",IFS(CS17="A",Montagem!$H$30,CU17="T","Realizar a maior quantidade de repetições por "&CM16&" segundos | ",CU17="I",IF(CT17="U","Manter a posição por "&CM16&" segundos de um lado e trocar para o outro na sequência | ","Manter a posição por "&CM16&" segundos | "),CT17="A","Realizar alternadamente "&CM16&" repetições cada lado | ",CT17="U","Realizar "&CM16&" repetições de um lado e trocar para o outro na sequência | ",CS17="P",OFFSET(Biblioteca!$H$2,MATCH(CT16,Biblioteca!$A$3:$A$200,0),0),TRUE,"")) -> Realizar 10 repetições de um lado e trocar para o outro na sequência | | CL17: =IF(CH16="","",IFS(CS17="H","Carga Sugerida: "&ROUNDUP(CV16/2,0)&" kg de cada lado (Total: "&ROUNDUP(CV16/2,0)*2&" kg)",CS17="C","Este exercício usa o Peso Corporal como carga",CS17="E","Este exercício usa a resistência da banda elástica como carga",CS17="O","Carga Sugerida: "&INT(CV16)&" kg",TRUE,"")) -> Este exercício usa o Peso Corporal como carga | CR17: =CR16 -> 1 | CS17: =LEFT(CV17) -> C | CT17: =MID(CV17,2,1) -> U | CU17: =RIGHT(CV17) -> R | CV17: =IF(CT16="","",OFFSET(Biblioteca!$I$2,MATCH(CT16,Biblioteca!$A$3:$A$200,0),0)) -> CUR | CY17: =IF(CY16="","",IFS(DJ17="A",Montagem!$I$30,DL17="T","Realizar a maior quantidade de repetições por "&DD16&" segundos | ",DL17="I",IF(DK17="U","Manter a posição por "&DD16&" segundos de um lado e trocar para o outro na sequência | ","Manter a posição por "&DD16&" segundos | "),DK17="A","Realizar alternadamente "&DD16&" repetições cada lado | ",DK17="U","Realizar "&DD16&" repetições de um lado e trocar para o outro na sequência | ",DJ17="P",OFFSET(Biblioteca!$H$2,MATCH(DK16,Biblioteca!$A$3:$A$200,0),0),TRUE,"")) | DC17: =IF(CY16="","",IFS(DJ17="H","Carga Sugerida: "&ROUNDUP(DM16/2,0)&" kg de cada lado (Total: "&ROUNDUP(DM16/2,0)*2&" kg)",DJ17="C","Este exercício usa o Peso Corporal como carga",DJ17="E","Este exercício usa a resistência da banda elástica como carga",DJ17="O","Carga Sugerida: "&INT(DM16)&" kg",TRUE,"")) | DI17: =DI16 -> 1 | DJ17: =LEFT(DM17) | DK17: =MID(DM17,2,1) | DL17: =RIGHT(DM17) | DM17: =IF(DK16="","",OFFSET(Biblioteca!$I$2,MATCH(DK16,Biblioteca!$A$3:$A$200,0),0)) | DP17: Sessões na Semana | DQ17: =J2 -> 6
A18: =IF(M18="","",HYPERLINK(OFFSET(Biblioteca!$B$2,MATCH(M18,Biblioteca!$A$3:$A$200,0),0),M18)) -> Mobilidade de Pelve no solo | D18: =Montagem!Q17 -> Seriado | E18: =Montagem!R17 -> 2 | F18: =Montagem!S17 -> 10 | G18: =Montagem!T17 -> 10 | H18: =Montagem!U17 -> 1 | I18: =Montagem!V17 -> 1 | K18: =Montagem!K17 -> 2 | L18: =Montagem!W17 -> 0 | M18: =Montagem!L17 -> Mobilidade de Pelve no solo | N18: =Montagem!X17 | O18: =IF(N18="",L18,N18) -> 0 | P18: =IF(L19="C",'Dados de Base'!$D$5*0.1,IF(L19="E",5,IF(J18="",O18,J18))) -> 6.3 | R18: =IF(AD18="","",HYPERLINK(OFFSET(Biblioteca!$B$2,MATCH(AD18,Biblioteca!$A$3:$A$200,0),0),AD18)) -> Mobilidade Posterior de Coxa | U18: =Montagem!AF17 -> Seriado | V18: =Montagem!AG17 -> 2 | W18: =Montagem!AH17 -> 10 | X18: =Montagem!AI17 -> 10 | Y18: =Montagem!AJ17 -> 1 | Z18: =Montagem!AK17 -> 1 | AB18: =Montagem!Z17 -> 2 | AC18: =Montagem!AL17 -> 0 | AD18: =Montagem!AA17 -> Mobilidade Posterior de Coxa | AE18: =Montagem!AM17 | AF18: =IF(AE18="",AC18,AE18) -> 0 | AG18: =IF(AC19="C",'Dados de Base'!$D$5*0.1,IF(AC19="E",5,IF(AA18="",AF18,AA18))) -> 6.3 | AI18: =IF(AU18="","",HYPERLINK(OFFSET(Biblioteca!$B$2,MATCH(AU18,Biblioteca!$A$3:$A$200,0),0),AU18)) -> Mobilidade de tornozelo | AL18: =Montagem!AU17 -> Seriado | AM18: =Montagem!AV17 -> 2 | AN18: =Montagem!AW17 -> 10 | AO18: =Montagem!AX17 -> 10 | AP18: =Montagem!AY17 -> 1 | AQ18: =Montagem!AZ17 -> 1 | AS18: =Montagem!AO17 -> 2 | AT18: =Montagem!BA17 -> 0 | AU18: =Montagem!AP17 -> Mobilidade de tornozelo | AV18: =Montagem!BB17 | AW18: =IF(AV18="",AT18,AV18) -> 0 | AX18: =IF(AT19="C",'Dados de Base'!$D$5*0.1,IF(AT19="E",5,IF(AR18="",AW18,AR18))) -> 6.3 | AZ18: =IF(BL18="","",HYPERLINK(OFFSET(Biblioteca!$B$2,MATCH(BL18,Biblioteca!$A$3:$A$200,0),0),BL18)) -> Alongamento Iliotibial III | BC18: =Montagem!BJ17 -> Seriado | BD18: =Montagem!BK17 -> 2 | BE18: =Montagem!BL17 -> 10 | BF18: =Montagem!BM17 -> 10 | BG18: =Montagem!BN17 -> 1 | BH18: =Montagem!BO17 -> 1 | BJ18: =Montagem!BD17 -> 2 | BK18: =Montagem!BP17 -> 0 | BL18: =Montagem!BE17 -> Alongamento Iliotibial III | BM18: =Montagem!BQ17 | BN18: =IF(BM18="",BK18,BM18) -> 0 | BO18: =IF(BK19="C",'Dados de Base'!$D$5*0.1,IF(BK19="E",5,IF(BI18="",BN18,BI18))) -> 6.3 | BQ18: =IF(CC18="","",HYPERLINK(OFFSET(Biblioteca!$B$2,MATCH(CC18,Biblioteca!$A$3:$A$200,0),0),CC18)) -> Mobilidade de Pelve na bola | BT18: =Montagem!BY17 -> Seriado | BU18: =Montagem!BZ17 -> 2 | BV18: =Montagem!CA17 -> 10 | BW18: =Montagem!CB17 -> 10 | BX18: =Montagem!CC17 -> 1 | BY18: =Montagem!CD17 -> 1 | CA18: =Montagem!BS17 -> 2 | CB18: =Montagem!CE17 -> 0 | CC18: =Montagem!BT17 -> Mobilidade de Pelve na bola | CD18: =Montagem!CF17 | CE18: =IF(CD18="",CB18,CD18) -> 0 | CF18: =IF(CB19="C",'Dados de Base'!$D$5*0.1,IF(CB19="E",5,IF(BZ18="",CE18,BZ18))) -> 6.3 | CH18: =IF(CT18="","",HYPERLINK(OFFSET(Biblioteca!$B$2,MATCH(CT18,Biblioteca!$A$3:$A$200,0),0),CT18)) -> Mobilidade de Quadril - Iliopsoas | CK18: =Montagem!CN17 -> Seriado | CL18: =Montagem!CO17 -> 2 | CM18: =Montagem!CP17 -> 10 | CN18: =Montagem!CQ17 -> 10 | CO18: =Montagem!CR17 -> 0 | CP18: =Montagem!CS17 -> 1 | CR18: =Montagem!CH17 -> 2 | CS18: =Montagem!CT17 -> 0 | CT18: =Montagem!CI17 -> Mobilidade de Quadril - Iliopsoas | CU18: =Montagem!CU17 | CV18: =IF(CU18="",CS18,CU18) -> 0 | CW18: =IF(CS19="C",'Dados de Base'!$D$5*0.1,IF(CS19="E",5,IF(CQ18="",CV18,CQ18))) -> 6.3 | CY18: =IF(DK18="","",HYPERLINK(OFFSET(Biblioteca!$B$2,MATCH(DK18,Biblioteca!$A$3:$A$200,0),0),DK18)) | DB18: =Montagem!DC17 | DC18: =Montagem!DD17 | DD18: =Montagem!DE17 | DE18: =Montagem!DF17 | DF18: =Montagem!DG17 | DG18: =Montagem!DH17 | DI18: =Montagem!CW17 -> 1 | DJ18: =Montagem!DI17 | DK18: =Montagem!CX17 | DL18: =Montagem!DJ17 | DM18: =IF(DL18="",DJ18,DL18) | DN18: =IF(DJ19="C",'Dados de Base'!$D$5*0.1,IF(DJ19="E",5,IF(DH18="",DM18,DH18))) | DP18: Realizadas | DQ18: =IF(L80=0,0,1)+IF(AC80=0,0,1)+IF(AT80=0,0,1)+IF(BK80=0,0,1)+IF(CB80=0,0,1)+IF(CS80=0,0,1)+IF(DJ80=0,0,1) -> 0
A19: =IF(A18="","",IFS(L19="A",Montagem!$C$30,N19="T","Realizar a maior quantidade de repetições por "&F18&" segundos | ",N19="I",IF(M19="U","Manter a posição por "&F18&" segundos de um lado e trocar para o outro na sequência | ","Manter a posição por "&F18&" segundos | "),M19="A","Realizar alternadamente "&F18&" repetições cada lado | ",M19="U","Realizar "&F18&" repetições de um lado e trocar para o outro na sequência | ",L19="P",OFFSET(Biblioteca!$H$2,MATCH(M18,Biblioteca!$A$3:$A$200,0),0),TRUE,"")) | E19: =IF(A18="","",IFS(L19="H","Carga Sugerida: "&ROUNDUP(O18/2,0)&" kg de cada lado (Total: "&ROUNDUP(O18/2,0)*2&" kg)",L19="C","Este exercício usa o Peso Corporal como carga",L19="E","Este exercício usa a resistência da banda elástica como carga",L19="O","Carga Sugerida: "&INT(O18)&" kg",TRUE,"")) -> Este exercício usa o Peso Corporal como carga | K19: =K18 -> 2 | L19: =LEFT(O19) -> C | M19: =MID(O19,2,1) -> O | N19: =RIGHT(O19) -> R | O19: =IF(M18="","",OFFSET(Biblioteca!$I$2,MATCH(M18,Biblioteca!$A$3:$A$200,0),0)) -> COR | R19: =IF(R18="","",IFS(AC19="A",Montagem!$D$30,AE19="T","Realizar a maior quantidade de repetições por "&W18&" segundos | ",AE19="I",IF(AD19="U","Manter a posição por "&W18&" segundos de um lado e trocar para o outro na sequência | ","Manter a posição por "&W18&" segundos | "),AD19="A","Realizar alternadamente "&W18&" repetições cada lado | ",AD19="U","Realizar "&W18&" repetições de um lado e trocar para o outro na sequência | ",AC19="P",OFFSET(Biblioteca!$H$2,MATCH(AD18,Biblioteca!$A$3:$A$200,0),0),TRUE,"")) | V19: =IF(R18="","",IFS(AC19="H","Carga Sugerida: "&ROUNDUP(AF18/2,0)&" kg de cada lado (Total: "&ROUNDUP(AF18/2,0)*2&" kg)",AC19="C","Este exercício usa o Peso Corporal como carga",AC19="E","Este exercício usa a resistência da banda elástica como carga",AC19="O","Carga Sugerida: "&INT(AF18)&" kg",TRUE,"")) -> Este exercício usa o Peso Corporal como carga | AB19: =AB18 -> 2 | AC19: =LEFT(AF19) -> C | AD19: =MID(AF19,2,1) -> O | AE19: =RIGHT(AF19) -> R | AF19: =IF(AD18="","",OFFSET(Biblioteca!$I$2,MATCH(AD18,Biblioteca!$A$3:$A$200,0),0)) -> COR | AI19: =IF(AI18="","",IFS(AT19="A",Montagem!$E$30,AV19="T","Realizar a maior quantidade de repetições por "&AN18&" segundos | ",AV19="I",IF(AU19="U","Manter a posição por "&AN18&" segundos de um lado e trocar para o outro na sequência | ","Manter a posição por "&AN18&" segundos | "),AU19="A","Realizar alternadamente "&AN18&" repetições cada lado | ",AU19="U","Realizar "&AN18&" repetições de um lado e trocar para o outro na sequência | ",AT19="P",OFFSET(Biblioteca!$H$2,MATCH(AU18,Biblioteca!$A$3:$A$200,0),0),TRUE,"")) -> Realizar 10 repetições de um lado e trocar para o outro na sequência | | AM19: =IF(AI18="","",IFS(AT19="H","Carga Sugerida: "&ROUNDUP(AW18/2,0)&" kg de cada lado (Total: "&ROUNDUP(AW18/2,0)*2&" kg)",AT19="C","Este exercício usa o Peso Corporal como carga",AT19="E","Este exercício usa a resistência da banda elástica como carga",AT19="O","Carga Sugerida: "&INT(AW18)&" kg",TRUE,"")) -> Este exercício usa o Peso Corporal como carga | AS19: =AS18 -> 2 | AT19: =LEFT(AW19) -> C | AU19: =MID(AW19,2,1) -> U | AV19: =RIGHT(AW19) -> R | AW19: =IF(AU18="","",OFFSET(Biblioteca!$I$2,MATCH(AU18,Biblioteca!$A$3:$A$200,0),0)) -> CUR | AZ19: =IF(AZ18="","",IFS(BK19="A",Montagem!$F$30,BM19="T","Realizar a maior quantidade de repetições por "&BE18&" segundos | ",BM19="I",IF(BL19="U","Manter a posição por "&BE18&" segundos de um lado e trocar para o outro na sequência | ","Manter a posição por "&BE18&" segundos | "),BL19="A","Realizar alternadamente "&BE18&" repetições cada lado | ",BL19="U","Realizar "&BE18&" repetições de um lado e trocar para o outro na sequência | ",BK19="P",OFFSET(Biblioteca!$H$2,MATCH(BL18,Biblioteca!$A$3:$A$200,0),0),TRUE,"")) -> Realizar 10 repetições de um lado e trocar para o outro na sequência | | BD19: =IF(AZ18="","",IFS(BK19="H","Carga Sugerida: "&ROUNDUP(BN18/2,0)&" kg de cada lado (Total: "&ROUNDUP(BN18/2,0)*2&" kg)",BK19="C","Este exercício usa o Peso Corporal como carga",BK19="E","Este exercício usa a resistência da banda elástica como carga",BK19="O","Carga Sugerida: "&INT(BN18)&" kg",TRUE,"")) -> Este exercício usa o Peso Corporal como carga | BJ19: =BJ18 -> 2 | BK19: =LEFT(BN19) -> C | BL19: =MID(BN19,2,1) -> U | BM19: =RIGHT(BN19) -> R | BN19: =IF(BL18="","",OFFSET(Biblioteca!$I$2,MATCH(BL18,Biblioteca!$A$3:$A$200,0),0)) -> CUR | BQ19: =IF(BQ18="","",IFS(CB19="A",Montagem!$G$30,CD19="T","Realizar a maior quantidade de repetições por "&BV18&" segundos | ",CD19="I",IF(CC19="U","Manter a posição por "&BV18&" segundos de um lado e trocar para o outro na sequência | ","Manter a posição por "&BV18&" segundos | "),CC19="A","Realizar alternadamente "&BV18&" repetições cada lado | ",CC19="U","Realizar "&BV18&" repetições de um lado e trocar para o outro na sequência | ",CB19="P",OFFSET(Biblioteca!$H$2,MATCH(CC18,Biblioteca!$A$3:$A$200,0),0),TRUE,"")) | BU19: =IF(BQ18="","",IFS(CB19="H","Carga Sugerida: "&ROUNDUP(CE18/2,0)&" kg de cada lado (Total: "&ROUNDUP(CE18/2,0)*2&" kg)",CB19="C","Este exercício usa o Peso Corporal como carga",CB19="E","Este exercício usa a resistência da banda elástica como carga",CB19="O","Carga Sugerida: "&INT(CE18)&" kg",TRUE,"")) -> Este exercício usa o Peso Corporal como carga | CA19: =CA18 -> 2 | CB19: =LEFT(CE19) -> C | CC19: =MID(CE19,2,1) -> O | CD19: =RIGHT(CE19) -> R | CE19: =IF(CC18="","",OFFSET(Biblioteca!$I$2,MATCH(CC18,Biblioteca!$A$3:$A$200,0),0)) -> COR | CH19: =IF(CH18="","",IFS(CS19="A",Montagem!$H$30,CU19="T","Realizar a maior quantidade de repetições por "&CM18&" segundos | ",CU19="I",IF(CT19="U","Manter a posição por "&CM18&" segundos de um lado e trocar para o outro na sequência | ","Manter a posição por "&CM18&" segundos | "),CT19="A","Realizar alternadamente "&CM18&" repetições cada lado | ",CT19="U","Realizar "&CM18&" repetições de um lado e trocar para o outro na sequência | ",CS19="P",OFFSET(Biblioteca!$H$2,MATCH(CT18,Biblioteca!$A$3:$A$200,0),0),TRUE,"")) | CL19: =IF(CH18="","",IFS(CS19="H","Carga Sugerida: "&ROUNDUP(CV18/2,0)&" kg de cada lado (Total: "&ROUNDUP(CV18/2,0)*2&" kg)",CS19="C","Este exercício usa o Peso Corporal como carga",CS19="E","Este exercício usa a resistência da banda elástica como carga",CS19="O","Carga Sugerida: "&INT(CV18)&" kg",TRUE,"")) -> Este exercício usa o Peso Corporal como carga | CR19: =CR18 -> 2 | CS19: =LEFT(CV19) -> C | CT19: =MID(CV19,2,1) -> O | CU19: =RIGHT(CV19) -> R | CV19: =IF(CT18="","",OFFSET(Biblioteca!$I$2,MATCH(CT18,Biblioteca!$A$3:$A$200,0),0)) -> COR | CY19: =IF(CY18="","",IFS(DJ19="A",Montagem!$I$30,DL19="T","Realizar a maior quantidade de repetições por "&DD18&" segundos | ",DL19="I",IF(DK19="U","Manter a posição por "&DD18&" segundos de um lado e trocar para o outro na sequência | ","Manter a posição por "&DD18&" segundos | "),DK19="A","Realizar alternadamente "&DD18&" repetições cada lado | ",DK19="U","Realizar "&DD18&" repetições de um lado e trocar para o outro na sequência | ",DJ19="P",OFFSET(Biblioteca!$H$2,MATCH(DK18,Biblioteca!$A$3:$A$200,0),0),TRUE,"")) | DC19: =IF(CY18="","",IFS(DJ19="H","Carga Sugerida: "&ROUNDUP(DM18/2,0)&" kg de cada lado (Total: "&ROUNDUP(DM18/2,0)*2&" kg)",DJ19="C","Este exercício usa o Peso Corporal como carga",DJ19="E","Este exercício usa a resistência da banda elástica como carga",DJ19="O","Carga Sugerida: "&INT(DM18)&" kg",TRUE,"")) | DI19: =DI18 -> 1 | DJ19: =LEFT(DM19) | DK19: =MID(DM19,2,1) | DL19: =RIGHT(DM19) | DM19: =IF(DK18="","",OFFSET(Biblioteca!$I$2,MATCH(DK18,Biblioteca!$A$3:$A$200,0),0)) | DP19: Constância | DQ19: =IF(DQ17=0,0,DQ18/DQ17) -> 0
A20: =IF(M20="","",HYPERLINK(OFFSET(Biblioteca!$B$2,MATCH(M20,Biblioteca!$A$3:$A$200,0),0),M20)) -> Mobilidade de Pelve na bola | D20: =Montagem!Q18 -> Seriado | E20: =Montagem!R18 -> 2 | F20: =Montagem!S18 -> 10 | G20: =Montagem!T18 -> 10 | H20: =Montagem!U18 -> 1 | I20: =Montagem!V18 -> 1 | K20: =Montagem!K18 -> 3 | L20: =Montagem!W18 -> 0 | M20: =Montagem!L18 -> Mobilidade de Pelve na bola | N20: =Montagem!X18 | O20: =IF(N20="",L20,N20) -> 0 | P20: =IF(L21="C",'Dados de Base'!$D$5*0.1,IF(L21="E",5,IF(J20="",O20,J20))) -> 6.3 | R20: =IF(AD20="","",HYPERLINK(OFFSET(Biblioteca!$B$2,MATCH(AD20,Biblioteca!$A$3:$A$200,0),0),AD20)) -> Mobilidade Quadril - Sumô | U20: =Montagem!AF18 -> Seriado | V20: =Montagem!AG18 -> 2 | W20: =Montagem!AH18 -> 10 | X20: =Montagem!AI18 -> 10 | Y20: =Montagem!AJ18 -> 1 | Z20: =Montagem!AK18 -> 1 | AB20: =Montagem!Z18 -> 3 | AC20: =Montagem!AL18 -> 0 | AD20: =Montagem!AA18 -> Mobilidade Quadril - Sumô | AE20: =Montagem!AM18 | AF20: =IF(AE20="",AC20,AE20) -> 0 | AG20: =IF(AC21="C",'Dados de Base'!$D$5*0.1,IF(AC21="E",5,IF(AA20="",AF20,AA20))) -> 6.3 | AI20: =IF(AU20="","",HYPERLINK(OFFSET(Biblioteca!$B$2,MATCH(AU20,Biblioteca!$A$3:$A$200,0),0),AU20)) -> Prancha | AL20: =Montagem!AU18 -> Seriado | AM20: =Montagem!AV18 -> 1 | AN20: =Montagem!AW18 -> 50 | AO20: =Montagem!AX18 -> 60 | AP20: =Montagem!AY18 -> 0 | AQ20: =Montagem!AZ18 -> 1 | AS20: =Montagem!AO18 -> 3 | AT20: =Montagem!BA18 -> 0 | AU20: =Montagem!AP18 -> Prancha | AV20: =Montagem!BB18 | AW20: =IF(AV20="",AT20,AV20) -> 0 | AX20: =IF(AT21="C",'Dados de Base'!$D$5*0.1,IF(AT21="E",5,IF(AR20="",AW20,AR20))) -> 6.3 | AZ20: =IF(BL20="","",HYPERLINK(OFFSET(Biblioteca!$B$2,MATCH(BL20,Biblioteca!$A$3:$A$200,0),0),BL20)) -> Alongamento piriforme com bola | BC20: =Montagem!BJ18 -> Seriado | BD20: =Montagem!BK18 -> 2 | BE20: =Montagem!BL18 -> 10 | BF20: =Montagem!BM18 -> 10 | BG20: =Montagem!BN18 -> 1 | BH20: =Montagem!BO18 -> 1 | BJ20: =Montagem!BD18 -> 3 | BK20: =Montagem!BP18 -> 0 | BL20: =Montagem!BE18 -> Alongamento piriforme com bola | BM20: =Montagem!BQ18 | BN20: =IF(BM20="",BK20,BM20) -> 0 | BO20: =IF(BK21="C",'Dados de Base'!$D$5*0.1,IF(BK21="E",5,IF(BI20="",BN20,BI20))) -> 6.3 | BQ20: =IF(CC20="","",HYPERLINK(OFFSET(Biblioteca!$B$2,MATCH(CC20,Biblioteca!$A$3:$A$200,0),0),CC20)) -> Mobilidade Quadril - Abdução/Adução | BT20: =Montagem!BY18 -> Seriado | BU20: =Montagem!BZ18 -> 2 | BV20: =Montagem!CA18 -> 10 | BW20: =Montagem!CB18 -> 10 | BX20: =Montagem!CC18 -> 1 | BY20: =Montagem!CD18 -> 1 | CA20: =Montagem!BS18 -> 3 | CB20: =Montagem!CE18 -> 0 | CC20: =Montagem!BT18 -> Mobilidade Quadril - Abdução/Adução | CD20: =Montagem!CF18 | CE20: =IF(CD20="",CB20,CD20) -> 0 | CF20: =IF(CB21="C",'Dados de Base'!$D$5*0.1,IF(CB21="E",5,IF(BZ20="",CE20,BZ20))) -> 6.3 | CH20: =IF(CT20="","",HYPERLINK(OFFSET(Biblioteca!$B$2,MATCH(CT20,Biblioteca!$A$3:$A$200,0),0),CT20)) -> Skipping Baixo | CK20: =Montagem!CN18 -> Seriado | CL20: =Montagem!CO18 -> 1 | CM20: =Montagem!CP18 -> 30 | CN20: =Montagem!CQ18 -> 30 | CO20: =Montagem!CR18 -> 0 | CP20: =Montagem!CS18 -> 1 | CR20: =Montagem!CH18 -> 3 | CS20: =Montagem!CT18 -> 0 | CT20: =Montagem!CI18 -> Skipping Baixo | CU20: =Montagem!CU18 | CV20: =IF(CU20="",CS20,CU20) -> 0 | CW20: =IF(CS21="C",'Dados de Base'!$D$5*0.1,IF(CS21="E",5,IF(CQ20="",CV20,CQ20))) -> 6.3 | CY20: =IF(DK20="","",HYPERLINK(OFFSET(Biblioteca!$B$2,MATCH(DK20,Biblioteca!$A$3:$A$200,0),0),DK20)) | DB20: =Montagem!DC18 | DC20: =Montagem!DD18 | DD20: =Montagem!DE18 | DE20: =Montagem!DF18 | DF20: =Montagem!DG18 | DG20: =Montagem!DH18 | DI20: =Montagem!CW18 -> 1 | DJ20: =Montagem!DI18 | DK20: =Montagem!CX18 | DL20: =Montagem!DJ18 | DM20: =IF(DL20="",DJ20,DL20) | DN20: =IF(DJ21="C",'Dados de Base'!$D$5*0.1,IF(DJ21="E",5,IF(DH20="",DM20,DH20))) | DP20: Monotonia | DQ20: =IF(DQ14=0,0,DQ13/DQ14) -> 0
A21: =IF(A20="","",IFS(L21="A",Montagem!$C$30,N21="T","Realizar a maior quantidade de repetições por "&F20&" segundos | ",N21="I",IF(M21="U","Manter a posição por "&F20&" segundos de um lado e trocar para o outro na sequência | ","Manter a posição por "&F20&" segundos | "),M21="A","Realizar alternadamente "&F20&" repetições cada lado | ",M21="U","Realizar "&F20&" repetições de um lado e trocar para o outro na sequência | ",L21="P",OFFSET(Biblioteca!$H$2,MATCH(M20,Biblioteca!$A$3:$A$200,0),0),TRUE,"")) | E21: =IF(A20="","",IFS(L21="H","Carga Sugerida: "&ROUNDUP(O20/2,0)&" kg de cada lado (Total: "&ROUNDUP(O20/2,0)*2&" kg)",L21="C","Este exercício usa o Peso Corporal como carga",L21="E","Este exercício usa a resistência da banda elástica como carga",L21="O","Carga Sugerida: "&INT(O20)&" kg",TRUE,"")) -> Este exercício usa o Peso Corporal como carga | K21: =K20 -> 3 | L21: =LEFT(O21) -> C | M21: =MID(O21,2,1) -> O | N21: =RIGHT(O21) -> R | O21: =IF(M20="","",OFFSET(Biblioteca!$I$2,MATCH(M20,Biblioteca!$A$3:$A$200,0),0)) -> COR | R21: =IF(R20="","",IFS(AC21="A",Montagem!$D$30,AE21="T","Realizar a maior quantidade de repetições por "&W20&" segundos | ",AE21="I",IF(AD21="U","Manter a posição por "&W20&" segundos de um lado e trocar para o outro na sequência | ","Manter a posição por "&W20&" segundos | "),AD21="A","Realizar alternadamente "&W20&" repetições cada lado | ",AD21="U","Realizar "&W20&" repetições de um lado e trocar para o outro na sequência | ",AC21="P",OFFSET(Biblioteca!$H$2,MATCH(AD20,Biblioteca!$A$3:$A$200,0),0),TRUE,"")) | V21: =IF(R20="","",IFS(AC21="H","Carga Sugerida: "&ROUNDUP(AF20/2,0)&" kg de cada lado (Total: "&ROUNDUP(AF20/2,0)*2&" kg)",AC21="C","Este exercício usa o Peso Corporal como carga",AC21="E","Este exercício usa a resistência da banda elástica como carga",AC21="O","Carga Sugerida: "&INT(AF20)&" kg",TRUE,"")) -> Este exercício usa o Peso Corporal como carga | AB21: =AB20 -> 3 | AC21: =LEFT(AF21) -> C | AD21: =MID(AF21,2,1) -> O | AE21: =RIGHT(AF21) -> R | AF21: =IF(AD20="","",OFFSET(Biblioteca!$I$2,MATCH(AD20,Biblioteca!$A$3:$A$200,0),0)) -> COR | AI21: =IF(AI20="","",IFS(AT21="A",Montagem!$E$30,AV21="T","Realizar a maior quantidade de repetições por "&AN20&" segundos | ",AV21="I",IF(AU21="U","Manter a posição por "&AN20&" segundos de um lado e trocar para o outro na sequência | ","Manter a posição por "&AN20&" segundos | "),AU21="A","Realizar alternadamente "&AN20&" repetições cada lado | ",AU21="U","Realizar "&AN20&" repetições de um lado e trocar para o outro na sequência | ",AT21="P",OFFSET(Biblioteca!$H$2,MATCH(AU20,Biblioteca!$A$3:$A$200,0),0),TRUE,"")) -> Manter a posição por 50 segundos | | AM21: =IF(AI20="","",IFS(AT21="H","Carga Sugerida: "&ROUNDUP(AW20/2,0)&" kg de cada lado (Total: "&ROUNDUP(AW20/2,0)*2&" kg)",AT21="C","Este exercício usa o Peso Corporal como carga",AT21="E","Este exercício usa a resistência da banda elástica como carga",AT21="O","Carga Sugerida: "&INT(AW20)&" kg",TRUE,"")) -> Este exercício usa o Peso Corporal como carga | AS21: =AS20 -> 3 | AT21: =LEFT(AW21) -> C | AU21: =MID(AW21,2,1) -> O | AV21: =RIGHT(AW21) -> I | AW21: =IF(AU20="","",OFFSET(Biblioteca!$I$2,MATCH(AU20,Biblioteca!$A$3:$A$200,0),0)) -> COI | AZ21: =IF(AZ20="","",IFS(BK21="A",Montagem!$F$30,BM21="T","Realizar a maior quantidade de repetições por "&BE20&" segundos | ",BM21="I",IF(BL21="U","Manter a posição por "&BE20&" segundos de um lado e trocar para o outro na sequência | ","Manter a posição por "&BE20&" segundos | "),BL21="A","Realizar alternadamente "&BE20&" repetições cada lado | ",BL21="U","Realizar "&BE20&" repetições de um lado e trocar para o outro na sequência | ",BK21="P",OFFSET(Biblioteca!$H$2,MATCH(BL20,Biblioteca!$A$3:$A$200,0),0),TRUE,"")) -> Realizar 10 repetições de um lado e trocar para o outro na sequência | | BD21: =IF(AZ20="","",IFS(BK21="H","Carga Sugerida: "&ROUNDUP(BN20/2,0)&" kg de cada lado (Total: "&ROUNDUP(BN20/2,0)*2&" kg)",BK21="C","Este exercício usa o Peso Corporal como carga",BK21="E","Este exercício usa a resistência da banda elástica como carga",BK21="O","Carga Sugerida: "&INT(BN20)&" kg",TRUE,"")) -> Este exercício usa o Peso Corporal como carga | BJ21: =BJ20 -> 3 | BK21: =LEFT(BN21) -> C | BL21: =MID(BN21,2,1) -> U | BM21: =RIGHT(BN21) -> R | BN21: =IF(BL20="","",OFFSET(Biblioteca!$I$2,MATCH(BL20,Biblioteca!$A$3:$A$200,0),0)) -> CUR | BQ21: =IF(BQ20="","",IFS(CB21="A",Montagem!$G$30,CD21="T","Realizar a maior quantidade de repetições por "&BV20&" segundos | ",CD21="I",IF(CC21="U","Manter a posição por "&BV20&" segundos de um lado e trocar para o outro na sequência | ","Manter a posição por "&BV20&" segundos | "),CC21="A","Realizar alternadamente "&BV20&" repetições cada lado | ",CC21="U","Realizar "&BV20&" repetições de um lado e trocar para o outro na sequência | ",CB21="P",OFFSET(Biblioteca!$H$2,MATCH(CC20,Biblioteca!$A$3:$A$200,0),0),TRUE,"")) -> Realizar 10 repetições de um lado e trocar para o outro na sequência | | BU21: =IF(BQ20="","",IFS(CB21="H","Carga Sugerida: "&ROUNDUP(CE20/2,0)&" kg de cada lado (Total: "&ROUNDUP(CE20/2,0)*2&" kg)",CB21="C","Este exercício usa o Peso Corporal como carga",CB21="E","Este exercício usa a resistência da banda elástica como carga",CB21="O","Carga Sugerida: "&INT(CE20)&" kg",TRUE,"")) -> Este exercício usa o Peso Corporal como carga | CA21: =CA20 -> 3 | CB21: =LEFT(CE21) -> C | CC21: =MID(CE21,2,1) -> U | CD21: =RIGHT(CE21) -> R | CE21: =IF(CC20="","",OFFSET(Biblioteca!$I$2,MATCH(CC20,Biblioteca!$A$3:$A$200,0),0)) -> CUR | CH21: =IF(CH20="","",IFS(CS21="A",Montagem!$H$30,CU21="T","Realizar a maior quantidade de repetições por "&CM20&" segundos | ",CU21="I",IF(CT21="U","Manter a posição por "&CM20&" segundos de um lado e trocar para o outro na sequência | ","Manter a posição por "&CM20&" segundos | "),CT21="A","Realizar alternadamente "&CM20&" repetições cada lado | ",CT21="U","Realizar "&CM20&" repetições de um lado e trocar para o outro na sequência | ",CS21="P",OFFSET(Biblioteca!$H$2,MATCH(CT20,Biblioteca!$A$3:$A$200,0),0),TRUE,"")) -> Realizar a maior quantidade de repetições por 30 segundos | | CL21: =IF(CH20="","",IFS(CS21="H","Carga Sugerida: "&ROUNDUP(CV20/2,0)&" kg de cada lado (Total: "&ROUNDUP(CV20/2,0)*2&" kg)",CS21="C","Este exercício usa o Peso Corporal como carga",CS21="E","Este exercício usa a resistência da banda elástica como carga",CS21="O","Carga Sugerida: "&INT(CV20)&" kg",TRUE,"")) -> Este exercício usa o Peso Corporal como carga | CR21: =CR20 -> 3 | CS21: =LEFT(CV21) -> C | CT21: =MID(CV21,2,1) -> O | CU21: =RIGHT(CV21) -> T | CV21: =IF(CT20="","",OFFSET(Biblioteca!$I$2,MATCH(CT20,Biblioteca!$A$3:$A$200,0),0)) -> COT | CY21: =IF(CY20="","",IFS(DJ21="A",Montagem!$I$30,DL21="T","Realizar a maior quantidade de repetições por "&DD20&" segundos | ",DL21="I",IF(DK21="U","Manter a posição por "&DD20&" segundos de um lado e trocar para o outro na sequência | ","Manter a posição por "&DD20&" segundos | "),DK21="A","Realizar alternadamente "&DD20&" repetições cada lado | ",DK21="U","Realizar "&DD20&" repetições de um lado e trocar para o outro na sequência | ",DJ21="P",OFFSET(Biblioteca!$H$2,MATCH(DK20,Biblioteca!$A$3:$A$200,0),0),TRUE,"")) | DC21: =IF(CY20="","",IFS(DJ21="H","Carga Sugerida: "&ROUNDUP(DM20/2,0)&" kg de cada lado (Total: "&ROUNDUP(DM20/2,0)*2&" kg)",DJ21="C","Este exercício usa o Peso Corporal como carga",DJ21="E","Este exercício usa a resistência da banda elástica como carga",DJ21="O","Carga Sugerida: "&INT(DM20)&" kg",TRUE,"")) | DI21: =DI20 -> 1 | DJ21: =LEFT(DM21) | DK21: =MID(DM21,2,1) | DL21: =RIGHT(DM21) | DM21: =IF(DK20="","",OFFSET(Biblioteca!$I$2,MATCH(DK20,Biblioteca!$A$3:$A$200,0),0)) | DP21: Strain | DQ21: =DQ20*DQ11 -> 0
A22: =IF(M22="","",HYPERLINK(OFFSET(Biblioteca!$B$2,MATCH(M22,Biblioteca!$A$3:$A$200,0),0),M22)) -> Mobilidade Quadril - Abdução/Adução | D22: =Montagem!Q19 -> Seriado | E22: =Montagem!R19 -> 2 | F22: =Montagem!S19 -> 10 | G22: =Montagem!T19 -> 10 | H22: =Montagem!U19 -> 1 | I22: =Montagem!V19 -> 1 | K22: =Montagem!K19 -> 4 | L22: =Montagem!W19 -> 0 | M22: =Montagem!L19 -> Mobilidade Quadril - Abdução/Adução | N22: =Montagem!X19 | O22: =IF(N22="",L22,N22) -> 0 | P22: =IF(L23="C",'Dados de Base'!$D$5*0.1,IF(L23="E",5,IF(J22="",O22,J22))) -> 6.3 | R22: =IF(AD22="","",HYPERLINK(OFFSET(Biblioteca!$B$2,MATCH(AD22,Biblioteca!$A$3:$A$200,0),0),AD22)) | U22: =Montagem!AF19 | V22: =Montagem!AG19 | W22: =Montagem!AH19 | X22: =Montagem!AI19 | Y22: =Montagem!AJ19 | Z22: =Montagem!AK19 | AB22: =Montagem!Z19 -> 4 | AC22: =Montagem!AL19 | AD22: =Montagem!AA19 | AE22: =Montagem!AM19 | AF22: =IF(AE22="",AC22,AE22) | AG22: =IF(AC23="C",'Dados de Base'!$D$5*0.1,IF(AC23="E",5,IF(AA22="",AF22,AA22))) | AI22: =IF(AU22="","",HYPERLINK(OFFSET(Biblioteca!$B$2,MATCH(AU22,Biblioteca!$A$3:$A$200,0),0),AU22)) | AL22: =Montagem!AU19 | AM22: =Montagem!AV19 | AN22: =Montagem!AW19 | AO22: =Montagem!AX19 | AP22: =Montagem!AY19 | AQ22: =Montagem!AZ19 | AS22: =Montagem!AO19 -> 4 | AT22: =Montagem!BA19 | AU22: =Montagem!AP19 | AV22: =Montagem!BB19 | AW22: =IF(AV22="",AT22,AV22) | AX22: =IF(AT23="C",'Dados de Base'!$D$5*0.1,IF(AT23="E",5,IF(AR22="",AW22,AR22))) | AZ22: =IF(BL22="","",HYPERLINK(OFFSET(Biblioteca!$B$2,MATCH(BL22,Biblioteca!$A$3:$A$200,0),0),BL22)) | BC22: =Montagem!BJ19 | BD22: =Montagem!BK19 | BE22: =Montagem!BL19 | BF22: =Montagem!BM19 | BG22: =Montagem!BN19 | BH22: =Montagem!BO19 | BJ22: =Montagem!BD19 -> 4 | BK22: =Montagem!BP19 | BL22: =Montagem!BE19 | BM22: =Montagem!BQ19 | BN22: =IF(BM22="",BK22,BM22) | BO22: =IF(BK23="C",'Dados de Base'!$D$5*0.1,IF(BK23="E",5,IF(BI22="",BN22,BI22))) | BQ22: =IF(CC22="","",HYPERLINK(OFFSET(Biblioteca!$B$2,MATCH(CC22,Biblioteca!$A$3:$A$200,0),0),CC22)) -> Alongamento Iliotibial III | BT22: =Montagem!BY19 -> Seriado | BU22: =Montagem!BZ19 -> 2 | BV22: =Montagem!CA19 -> 10 | BW22: =Montagem!CB19 -> 10 | BX22: =Montagem!CC19 -> 1 | BY22: =Montagem!CD19 -> 1 | CA22: =Montagem!BS19 -> 4 | CB22: =Montagem!CE19 -> 0 | CC22: =Montagem!BT19 -> Alongamento Iliotibial III | CD22: =Montagem!CF19 | CE22: =IF(CD22="",CB22,CD22) -> 0 | CF22: =IF(CB23="C",'Dados de Base'!$D$5*0.1,IF(CB23="E",5,IF(BZ22="",CE22,BZ22))) -> 6.3 | CH22: =IF(CT22="","",HYPERLINK(OFFSET(Biblioteca!$B$2,MATCH(CT22,Biblioteca!$A$3:$A$200,0),0),CT22)) -> Skipping Alto | CK22: =Montagem!CN19 -> Seriado | CL22: =Montagem!CO19 -> 1 | CM22: =Montagem!CP19 -> 30 | CN22: =Montagem!CQ19 -> 30 | CO22: =Montagem!CR19 -> 0 | CP22: =Montagem!CS19 -> 1 | CR22: =Montagem!CH19 -> 4 | CS22: =Montagem!CT19 -> 0 | CT22: =Montagem!CI19 -> Skipping Alto | CU22: =Montagem!CU19 | CV22: =IF(CU22="",CS22,CU22) -> 0 | CW22: =IF(CS23="C",'Dados de Base'!$D$5*0.1,IF(CS23="E",5,IF(CQ22="",CV22,CQ22))) -> 6.3 | CY22: =IF(DK22="","",HYPERLINK(OFFSET(Biblioteca!$B$2,MATCH(DK22,Biblioteca!$A$3:$A$200,0),0),DK22)) | DB22: =Montagem!DC19 | DC22: =Montagem!DD19 | DD22: =Montagem!DE19 | DE22: =Montagem!DF19 | DF22: =Montagem!DG19 | DG22: =Montagem!DH19 | DI22: =Montagem!CW19 -> 1 | DJ22: =Montagem!DI19 | DK22: =Montagem!CX19 | DL22: =Montagem!DJ19 | DM22: =IF(DL22="",DJ22,DL22) | DN22: =IF(DJ23="C",'Dados de Base'!$D$5*0.1,IF(DJ23="E",5,IF(DH22="",DM22,DH22))) | DP22: Notas do Treino | DQ22: =COUNTA(A75,R75,AI75,AZ75,BQ75,CH75,CY75) -> 0
